2019-12-04 15:37:31 base.py[line:440] INFO Adding job tentatively -- it will be properly scheduled when the scheduler starts
2019-12-04 15:37:31 base.py[line:881] INFO Added job "main" to job store "default"
2019-12-04 15:37:31 base.py[line:166] INFO Scheduler started
2019-12-04 15:37:55 base.py[line:440] INFO Adding job tentatively -- it will be properly scheduled when the scheduler starts
2019-12-04 15:37:55 base.py[line:881] INFO Added job "main" to job store "default"
2019-12-04 15:37:55 base.py[line:166] INFO Scheduler started
2019-12-04 15:38:12 base.py[line:440] INFO Adding job tentatively -- it will be properly scheduled when the scheduler starts
2019-12-04 15:38:12 base.py[line:881] INFO Added job "main" to job store "default"
2019-12-04 15:38:12 base.py[line:166] INFO Scheduler started
2019-12-04 15:39:00 base.py[line:123] INFO Running job "main (trigger: cron[month='1-12', day='4', hour='15', minute='1-59', second='0'], next run at: 2019-12-04 15:39:00 CST)" (scheduled at 2019-12-04 15:39:00+08:00)
2019-12-04 15:39:01 base.py[line:144] INFO Job "main (trigger: cron[month='1-12', day='4', hour='15', minute='1-59', second='0'], next run at: 2019-12-04 15:40:00 CST)" executed successfully
2019-12-04 15:40:00 base.py[line:123] INFO Running job "main (trigger: cron[month='1-12', day='4', hour='15', minute='1-59', second='0'], next run at: 2019-12-04 15:41:00 CST)" (scheduled at 2019-12-04 15:40:00+08:00)
2019-12-04 15:40:01 base.py[line:144] INFO Job "main (trigger: cron[month='1-12', day='4', hour='15', minute='1-59', second='0'], next run at: 2019-12-04 15:41:00 CST)" executed successfully
2019-12-05 09:15:04 base.py[line:440] INFO Adding job tentatively -- it will be properly scheduled when the scheduler starts
2019-12-05 09:15:04 base.py[line:881] INFO Added job "main" to job store "default"
2019-12-05 09:15:04 base.py[line:166] INFO Scheduler started
2019-12-05 09:16:00 base.py[line:123] INFO Running job "main (trigger: cron[month='1-12', day='5', hour='9', minute='1-59', second='0'], next run at: 2019-12-05 09:16:00 CST)" (scheduled at 2019-12-05 09:16:00+08:00)
2019-12-05 09:16:01 base.py[line:144] INFO Job "main (trigger: cron[month='1-12', day='5', hour='9', minute='1-59', second='0'], next run at: 2019-12-05 09:17:00 CST)" executed successfully
2019-12-05 09:17:00 base.py[line:123] INFO Running job "main (trigger: cron[month='1-12', day='5', hour='9', minute='1-59', second='0'], next run at: 2019-12-05 09:18:00 CST)" (scheduled at 2019-12-05 09:17:00+08:00)
2019-12-05 09:31:48 base.py[line:440] INFO Adding job tentatively -- it will be properly scheduled when the scheduler starts
2019-12-05 09:31:48 base.py[line:881] INFO Added job "main" to job store "default"
2019-12-05 09:31:48 base.py[line:166] INFO Scheduler started
2019-12-05 09:32:00 base.py[line:123] INFO Running job "main (trigger: cron[month='1-12', day='5', hour='9', minute='1-59', second='0'], next run at: 2019-12-05 09:32:00 CST)" (scheduled at 2019-12-05 09:32:00+08:00)
2019-12-05 09:32:01 base.py[line:144] INFO Job "main (trigger: cron[month='1-12', day='5', hour='9', minute='1-59', second='0'], next run at: 2019-12-05 09:33:00 CST)" executed successfully
2019-12-05 09:33:00 base.py[line:123] INFO Running job "main (trigger: cron[month='1-12', day='5', hour='9', minute='1-59', second='0'], next run at: 2019-12-05 09:34:00 CST)" (scheduled at 2019-12-05 09:33:00+08:00)
2019-12-05 09:33:01 base.py[line:144] INFO Job "main (trigger: cron[month='1-12', day='5', hour='9', minute='1-59', second='0'], next run at: 2019-12-05 09:34:00 CST)" executed successfully
2019-12-05 09:34:00 base.py[line:123] INFO Running job "main (trigger: cron[month='1-12', day='5', hour='9', minute='1-59', second='0'], next run at: 2019-12-05 09:35:00 CST)" (scheduled at 2019-12-05 09:34:00+08:00)
2019-12-05 09:34:01 base.py[line:144] INFO Job "main (trigger: cron[month='1-12', day='5', hour='9', minute='1-59', second='0'], next run at: 2019-12-05 09:35:00 CST)" executed successfully
2019-12-05 18:18:27 base.py[line:440] INFO Adding job tentatively -- it will be properly scheduled when the scheduler starts
2019-12-05 18:18:27 base.py[line:881] INFO Added job "main" to job store "default"
2019-12-05 18:18:27 base.py[line:166] INFO Scheduler started
2019-12-05 18:18:34 base.py[line:440] INFO Adding job tentatively -- it will be properly scheduled when the scheduler starts
2019-12-05 18:18:34 base.py[line:881] INFO Added job "main" to job store "default"
2019-12-05 18:18:34 base.py[line:166] INFO Scheduler started
2019-12-05 18:19:00 base.py[line:123] INFO Running job "main (trigger: cron[month='1-12', day='5', hour='18', minute='1-59', second='0'], next run at: 2019-12-05 18:19:00 CST)" (scheduled at 2019-12-05 18:19:00+08:00)
2019-12-05 18:19:02 base.py[line:131] ERROR Job "main (trigger: cron[month='1-12', day='5', hour='18', minute='1-59', second='0'], next run at: 2019-12-05 18:20:00 CST)" raised an exception
Traceback (most recent call last):
  File "E:\virtual_environment\time_series\lib\site-packages\apscheduler\executors\base.py", line 125, in run_job
    retval = job.func(*job.args, **job.kwargs)
  File "E:/time_series_analize/main.py", line 47, in main
    save_data(pred_results)
  File "E:\time_series_analize\utils\util.py", line 39, in save_data
    t = d[0], d[1], index, int(row['upper Count']), int(row['lower'], 1)
ValueError: int() base must be >= 2 and <= 36, or 0
2019-12-05 18:20:00 base.py[line:123] INFO Running job "main (trigger: cron[month='1-12', day='5', hour='18', minute='1-59', second='0'], next run at: 2019-12-05 18:21:00 CST)" (scheduled at 2019-12-05 18:20:00+08:00)
2019-12-05 18:20:01 base.py[line:131] ERROR Job "main (trigger: cron[month='1-12', day='5', hour='18', minute='1-59', second='0'], next run at: 2019-12-05 18:21:00 CST)" raised an exception
Traceback (most recent call last):
  File "E:\virtual_environment\time_series\lib\site-packages\apscheduler\executors\base.py", line 125, in run_job
    retval = job.func(*job.args, **job.kwargs)
  File "E:/time_series_analize/main.py", line 47, in main
    save_data(pred_results)
  File "E:\time_series_analize\utils\util.py", line 39, in save_data
    t = d[0], d[1], index, int(row['upper Count']), int(row['lower'], 1)
ValueError: int() base must be >= 2 and <= 36, or 0
2019-12-05 18:20:11 base.py[line:440] INFO Adding job tentatively -- it will be properly scheduled when the scheduler starts
2019-12-05 18:20:11 base.py[line:881] INFO Added job "main" to job store "default"
2019-12-05 18:20:11 base.py[line:166] INFO Scheduler started
2019-12-05 18:21:00 base.py[line:123] INFO Running job "main (trigger: cron[month='1-12', day='5', hour='18', minute='1-59', second='0'], next run at: 2019-12-05 18:21:00 CST)" (scheduled at 2019-12-05 18:21:00+08:00)
2019-12-05 18:21:01 base.py[line:131] ERROR Job "main (trigger: cron[month='1-12', day='5', hour='18', minute='1-59', second='0'], next run at: 2019-12-05 18:22:00 CST)" raised an exception
Traceback (most recent call last):
  File "E:\virtual_environment\time_series\lib\site-packages\apscheduler\executors\base.py", line 125, in run_job
    retval = job.func(*job.args, **job.kwargs)
  File "E:/time_series_analize/main.py", line 47, in main
    save_data(pred_results)
  File "E:\time_series_analize\utils\util.py", line 39, in save_data
    t = d[0], d[1], index, int(row['upper Count']), int(row['lower'], 1)
ValueError: int() base must be >= 2 and <= 36, or 0
2019-12-05 18:22:00 base.py[line:123] INFO Running job "main (trigger: cron[month='1-12', day='5', hour='18', minute='1-59', second='0'], next run at: 2019-12-05 18:23:00 CST)" (scheduled at 2019-12-05 18:22:00+08:00)
2019-12-05 18:22:01 base.py[line:131] ERROR Job "main (trigger: cron[month='1-12', day='5', hour='18', minute='1-59', second='0'], next run at: 2019-12-05 18:23:00 CST)" raised an exception
Traceback (most recent call last):
  File "E:\virtual_environment\time_series\lib\site-packages\apscheduler\executors\base.py", line 125, in run_job
    retval = job.func(*job.args, **job.kwargs)
  File "E:/time_series_analize/main.py", line 47, in main
    save_data(pred_results)
  File "E:\time_series_analize\utils\util.py", line 39, in save_data
    t = d[0], d[1], index, int(row['upper Count']), int(row['lower'], 1)
ValueError: int() base must be >= 2 and <= 36, or 0
2019-12-05 18:23:00 base.py[line:123] INFO Running job "main (trigger: cron[month='1-12', day='5', hour='18', minute='1-59', second='0'], next run at: 2019-12-05 18:24:00 CST)" (scheduled at 2019-12-05 18:23:00+08:00)
2019-12-05 18:23:01 base.py[line:131] ERROR Job "main (trigger: cron[month='1-12', day='5', hour='18', minute='1-59', second='0'], next run at: 2019-12-05 18:24:00 CST)" raised an exception
Traceback (most recent call last):
  File "E:\virtual_environment\time_series\lib\site-packages\apscheduler\executors\base.py", line 125, in run_job
    retval = job.func(*job.args, **job.kwargs)
  File "E:/time_series_analize/main.py", line 47, in main
    save_data(pred_results)
  File "E:\time_series_analize\utils\util.py", line 39, in save_data
    t = d[0], d[1], index, int(row['upper Count']), int(row['lower'], 1)
ValueError: int() base must be >= 2 and <= 36, or 0
2019-12-05 18:24:00 base.py[line:123] INFO Running job "main (trigger: cron[month='1-12', day='5', hour='18', minute='1-59', second='0'], next run at: 2019-12-05 18:25:00 CST)" (scheduled at 2019-12-05 18:24:00+08:00)
2019-12-05 18:24:01 base.py[line:131] ERROR Job "main (trigger: cron[month='1-12', day='5', hour='18', minute='1-59', second='0'], next run at: 2019-12-05 18:25:00 CST)" raised an exception
Traceback (most recent call last):
  File "E:\virtual_environment\time_series\lib\site-packages\apscheduler\executors\base.py", line 125, in run_job
    retval = job.func(*job.args, **job.kwargs)
  File "E:/time_series_analize/main.py", line 47, in main
    save_data(pred_results)
  File "E:\time_series_analize\utils\util.py", line 39, in save_data
    t = d[0], d[1], index, int(row['upper Count']), int(row['lower'], 1)
ValueError: int() base must be >= 2 and <= 36, or 0
2019-12-05 18:25:00 base.py[line:123] INFO Running job "main (trigger: cron[month='1-12', day='5', hour='18', minute='1-59', second='0'], next run at: 2019-12-05 18:26:00 CST)" (scheduled at 2019-12-05 18:25:00+08:00)
2019-12-05 18:25:01 base.py[line:131] ERROR Job "main (trigger: cron[month='1-12', day='5', hour='18', minute='1-59', second='0'], next run at: 2019-12-05 18:26:00 CST)" raised an exception
Traceback (most recent call last):
  File "E:\virtual_environment\time_series\lib\site-packages\apscheduler\executors\base.py", line 125, in run_job
    retval = job.func(*job.args, **job.kwargs)
  File "E:/time_series_analize/main.py", line 47, in main
    save_data(pred_results)
  File "E:\time_series_analize\utils\util.py", line 39, in save_data
    t = d[0], d[1], index, int(row['upper Count']), int(row['lower'], 1)
ValueError: int() base must be >= 2 and <= 36, or 0
2019-12-05 18:26:00 base.py[line:123] INFO Running job "main (trigger: cron[month='1-12', day='5', hour='18', minute='1-59', second='0'], next run at: 2019-12-05 18:27:00 CST)" (scheduled at 2019-12-05 18:26:00+08:00)
2019-12-05 18:26:01 base.py[line:131] ERROR Job "main (trigger: cron[month='1-12', day='5', hour='18', minute='1-59', second='0'], next run at: 2019-12-05 18:27:00 CST)" raised an exception
Traceback (most recent call last):
  File "E:\virtual_environment\time_series\lib\site-packages\apscheduler\executors\base.py", line 125, in run_job
    retval = job.func(*job.args, **job.kwargs)
  File "E:/time_series_analize/main.py", line 47, in main
    save_data(pred_results)
  File "E:\time_series_analize\utils\util.py", line 39, in save_data
    t = d[0], d[1], index, int(row['upper Count']), int(row['lower'], 1)
ValueError: int() base must be >= 2 and <= 36, or 0
2019-12-05 18:27:00 base.py[line:123] INFO Running job "main (trigger: cron[month='1-12', day='5', hour='18', minute='1-59', second='0'], next run at: 2019-12-05 18:28:00 CST)" (scheduled at 2019-12-05 18:27:00+08:00)
2019-12-05 18:27:01 base.py[line:131] ERROR Job "main (trigger: cron[month='1-12', day='5', hour='18', minute='1-59', second='0'], next run at: 2019-12-05 18:28:00 CST)" raised an exception
Traceback (most recent call last):
  File "E:\virtual_environment\time_series\lib\site-packages\apscheduler\executors\base.py", line 125, in run_job
    retval = job.func(*job.args, **job.kwargs)
  File "E:/time_series_analize/main.py", line 47, in main
    save_data(pred_results)
  File "E:\time_series_analize\utils\util.py", line 39, in save_data
    t = d[0], d[1], index, int(row['upper Count']), int(row['lower'], 1)
ValueError: int() base must be >= 2 and <= 36, or 0
2019-12-05 18:28:00 base.py[line:123] INFO Running job "main (trigger: cron[month='1-12', day='5', hour='18', minute='1-59', second='0'], next run at: 2019-12-05 18:29:00 CST)" (scheduled at 2019-12-05 18:28:00+08:00)
2019-12-05 18:28:01 base.py[line:131] ERROR Job "main (trigger: cron[month='1-12', day='5', hour='18', minute='1-59', second='0'], next run at: 2019-12-05 18:29:00 CST)" raised an exception
Traceback (most recent call last):
  File "E:\virtual_environment\time_series\lib\site-packages\apscheduler\executors\base.py", line 125, in run_job
    retval = job.func(*job.args, **job.kwargs)
  File "E:/time_series_analize/main.py", line 47, in main
    save_data(pred_results)
  File "E:\time_series_analize\utils\util.py", line 39, in save_data
    t = d[0], d[1], index, int(row['upper Count']), int(row['lower'], 1)
ValueError: int() base must be >= 2 and <= 36, or 0
2019-12-05 18:29:00 base.py[line:123] INFO Running job "main (trigger: cron[month='1-12', day='5', hour='18', minute='1-59', second='0'], next run at: 2019-12-05 18:30:00 CST)" (scheduled at 2019-12-05 18:29:00+08:00)
2019-12-05 18:29:01 base.py[line:131] ERROR Job "main (trigger: cron[month='1-12', day='5', hour='18', minute='1-59', second='0'], next run at: 2019-12-05 18:30:00 CST)" raised an exception
Traceback (most recent call last):
  File "E:\virtual_environment\time_series\lib\site-packages\apscheduler\executors\base.py", line 125, in run_job
    retval = job.func(*job.args, **job.kwargs)
  File "E:/time_series_analize/main.py", line 47, in main
    save_data(pred_results)
  File "E:\time_series_analize\utils\util.py", line 39, in save_data
    t = d[0], d[1], index, int(row['upper Count']), int(row['lower'], 1)
ValueError: int() base must be >= 2 and <= 36, or 0
2019-12-05 18:30:00 base.py[line:123] INFO Running job "main (trigger: cron[month='1-12', day='5', hour='18', minute='1-59', second='0'], next run at: 2019-12-05 18:31:00 CST)" (scheduled at 2019-12-05 18:30:00+08:00)
2019-12-05 18:30:01 base.py[line:131] ERROR Job "main (trigger: cron[month='1-12', day='5', hour='18', minute='1-59', second='0'], next run at: 2019-12-05 18:31:00 CST)" raised an exception
Traceback (most recent call last):
  File "E:\virtual_environment\time_series\lib\site-packages\apscheduler\executors\base.py", line 125, in run_job
    retval = job.func(*job.args, **job.kwargs)
  File "E:/time_series_analize/main.py", line 47, in main
    save_data(pred_results)
  File "E:\time_series_analize\utils\util.py", line 39, in save_data
    t = d[0], d[1], index, int(row['upper Count']), int(row['lower'], 1)
ValueError: int() base must be >= 2 and <= 36, or 0
2019-12-05 18:31:00 base.py[line:123] INFO Running job "main (trigger: cron[month='1-12', day='5', hour='18', minute='1-59', second='0'], next run at: 2019-12-05 18:32:00 CST)" (scheduled at 2019-12-05 18:31:00+08:00)
2019-12-05 18:31:01 base.py[line:131] ERROR Job "main (trigger: cron[month='1-12', day='5', hour='18', minute='1-59', second='0'], next run at: 2019-12-05 18:32:00 CST)" raised an exception
Traceback (most recent call last):
  File "E:\virtual_environment\time_series\lib\site-packages\apscheduler\executors\base.py", line 125, in run_job
    retval = job.func(*job.args, **job.kwargs)
  File "E:/time_series_analize/main.py", line 47, in main
    save_data(pred_results)
  File "E:\time_series_analize\utils\util.py", line 39, in save_data
    t = d[0], d[1], index, int(row['upper Count']), int(row['lower'], 1)
ValueError: int() base must be >= 2 and <= 36, or 0
2019-12-05 18:32:00 base.py[line:123] INFO Running job "main (trigger: cron[month='1-12', day='5', hour='18', minute='1-59', second='0'], next run at: 2019-12-05 18:33:00 CST)" (scheduled at 2019-12-05 18:32:00+08:00)
2019-12-05 18:32:01 base.py[line:131] ERROR Job "main (trigger: cron[month='1-12', day='5', hour='18', minute='1-59', second='0'], next run at: 2019-12-05 18:33:00 CST)" raised an exception
Traceback (most recent call last):
  File "E:\virtual_environment\time_series\lib\site-packages\apscheduler\executors\base.py", line 125, in run_job
    retval = job.func(*job.args, **job.kwargs)
  File "E:/time_series_analize/main.py", line 47, in main
    save_data(pred_results)
  File "E:\time_series_analize\utils\util.py", line 39, in save_data
    t = d[0], d[1], index, int(row['upper Count']), int(row['lower'], 1)
ValueError: int() base must be >= 2 and <= 36, or 0
2019-12-05 18:33:00 base.py[line:123] INFO Running job "main (trigger: cron[month='1-12', day='5', hour='18', minute='1-59', second='0'], next run at: 2019-12-05 18:34:00 CST)" (scheduled at 2019-12-05 18:33:00+08:00)
2019-12-05 18:33:01 base.py[line:131] ERROR Job "main (trigger: cron[month='1-12', day='5', hour='18', minute='1-59', second='0'], next run at: 2019-12-05 18:34:00 CST)" raised an exception
Traceback (most recent call last):
  File "E:\virtual_environment\time_series\lib\site-packages\apscheduler\executors\base.py", line 125, in run_job
    retval = job.func(*job.args, **job.kwargs)
  File "E:/time_series_analize/main.py", line 47, in main
    save_data(pred_results)
  File "E:\time_series_analize\utils\util.py", line 39, in save_data
    t = d[0], d[1], index, int(row['upper Count']), int(row['lower'], 1)
ValueError: int() base must be >= 2 and <= 36, or 0
2019-12-05 18:34:00 base.py[line:123] INFO Running job "main (trigger: cron[month='1-12', day='5', hour='18', minute='1-59', second='0'], next run at: 2019-12-05 18:35:00 CST)" (scheduled at 2019-12-05 18:34:00+08:00)
2019-12-05 18:34:01 base.py[line:131] ERROR Job "main (trigger: cron[month='1-12', day='5', hour='18', minute='1-59', second='0'], next run at: 2019-12-05 18:35:00 CST)" raised an exception
Traceback (most recent call last):
  File "E:\virtual_environment\time_series\lib\site-packages\apscheduler\executors\base.py", line 125, in run_job
    retval = job.func(*job.args, **job.kwargs)
  File "E:/time_series_analize/main.py", line 47, in main
    save_data(pred_results)
  File "E:\time_series_analize\utils\util.py", line 39, in save_data
    t = d[0], d[1], index, int(row['upper Count']), int(row['lower'], 1)
ValueError: int() base must be >= 2 and <= 36, or 0
2019-12-05 18:35:00 base.py[line:123] INFO Running job "main (trigger: cron[month='1-12', day='5', hour='18', minute='1-59', second='0'], next run at: 2019-12-05 18:36:00 CST)" (scheduled at 2019-12-05 18:35:00+08:00)
2019-12-05 18:35:01 base.py[line:131] ERROR Job "main (trigger: cron[month='1-12', day='5', hour='18', minute='1-59', second='0'], next run at: 2019-12-05 18:36:00 CST)" raised an exception
Traceback (most recent call last):
  File "E:\virtual_environment\time_series\lib\site-packages\apscheduler\executors\base.py", line 125, in run_job
    retval = job.func(*job.args, **job.kwargs)
  File "E:/time_series_analize/main.py", line 47, in main
    save_data(pred_results)
  File "E:\time_series_analize\utils\util.py", line 39, in save_data
    t = d[0], d[1], index, int(row['upper Count']), int(row['lower'], 1)
ValueError: int() base must be >= 2 and <= 36, or 0
2019-12-05 18:36:00 base.py[line:123] INFO Running job "main (trigger: cron[month='1-12', day='5', hour='18', minute='1-59', second='0'], next run at: 2019-12-05 18:37:00 CST)" (scheduled at 2019-12-05 18:36:00+08:00)
2019-12-05 18:36:01 base.py[line:131] ERROR Job "main (trigger: cron[month='1-12', day='5', hour='18', minute='1-59', second='0'], next run at: 2019-12-05 18:37:00 CST)" raised an exception
Traceback (most recent call last):
  File "E:\virtual_environment\time_series\lib\site-packages\apscheduler\executors\base.py", line 125, in run_job
    retval = job.func(*job.args, **job.kwargs)
  File "E:/time_series_analize/main.py", line 47, in main
    save_data(pred_results)
  File "E:\time_series_analize\utils\util.py", line 39, in save_data
    t = d[0], d[1], index, int(row['upper Count']), int(row['lower'], 1)
ValueError: int() base must be >= 2 and <= 36, or 0
2019-12-05 18:37:00 base.py[line:123] INFO Running job "main (trigger: cron[month='1-12', day='5', hour='18', minute='1-59', second='0'], next run at: 2019-12-05 18:38:00 CST)" (scheduled at 2019-12-05 18:37:00+08:00)
2019-12-05 18:37:01 base.py[line:131] ERROR Job "main (trigger: cron[month='1-12', day='5', hour='18', minute='1-59', second='0'], next run at: 2019-12-05 18:38:00 CST)" raised an exception
Traceback (most recent call last):
  File "E:\virtual_environment\time_series\lib\site-packages\apscheduler\executors\base.py", line 125, in run_job
    retval = job.func(*job.args, **job.kwargs)
  File "E:/time_series_analize/main.py", line 47, in main
    save_data(pred_results)
  File "E:\time_series_analize\utils\util.py", line 39, in save_data
    t = d[0], d[1], index, int(row['upper Count']), int(row['lower'], 1)
ValueError: int() base must be >= 2 and <= 36, or 0
2019-12-05 18:38:00 base.py[line:123] INFO Running job "main (trigger: cron[month='1-12', day='5', hour='18', minute='1-59', second='0'], next run at: 2019-12-05 18:39:00 CST)" (scheduled at 2019-12-05 18:38:00+08:00)
2019-12-05 18:38:01 base.py[line:131] ERROR Job "main (trigger: cron[month='1-12', day='5', hour='18', minute='1-59', second='0'], next run at: 2019-12-05 18:39:00 CST)" raised an exception
Traceback (most recent call last):
  File "E:\virtual_environment\time_series\lib\site-packages\apscheduler\executors\base.py", line 125, in run_job
    retval = job.func(*job.args, **job.kwargs)
  File "E:/time_series_analize/main.py", line 47, in main
    save_data(pred_results)
  File "E:\time_series_analize\utils\util.py", line 39, in save_data
    t = d[0], d[1], index, int(row['upper Count']), int(row['lower'], 1)
ValueError: int() base must be >= 2 and <= 36, or 0
2019-12-05 18:39:00 base.py[line:123] INFO Running job "main (trigger: cron[month='1-12', day='5', hour='18', minute='1-59', second='0'], next run at: 2019-12-05 18:40:00 CST)" (scheduled at 2019-12-05 18:39:00+08:00)
2019-12-05 18:39:01 base.py[line:131] ERROR Job "main (trigger: cron[month='1-12', day='5', hour='18', minute='1-59', second='0'], next run at: 2019-12-05 18:40:00 CST)" raised an exception
Traceback (most recent call last):
  File "E:\virtual_environment\time_series\lib\site-packages\apscheduler\executors\base.py", line 125, in run_job
    retval = job.func(*job.args, **job.kwargs)
  File "E:/time_series_analize/main.py", line 47, in main
    save_data(pred_results)
  File "E:\time_series_analize\utils\util.py", line 39, in save_data
    t = d[0], d[1], index, int(row['upper Count']), int(row['lower'], 1)
ValueError: int() base must be >= 2 and <= 36, or 0
2019-12-05 18:40:00 base.py[line:123] INFO Running job "main (trigger: cron[month='1-12', day='5', hour='18', minute='1-59', second='0'], next run at: 2019-12-05 18:41:00 CST)" (scheduled at 2019-12-05 18:40:00+08:00)
2019-12-05 18:40:01 base.py[line:131] ERROR Job "main (trigger: cron[month='1-12', day='5', hour='18', minute='1-59', second='0'], next run at: 2019-12-05 18:41:00 CST)" raised an exception
Traceback (most recent call last):
  File "E:\virtual_environment\time_series\lib\site-packages\apscheduler\executors\base.py", line 125, in run_job
    retval = job.func(*job.args, **job.kwargs)
  File "E:/time_series_analize/main.py", line 47, in main
    save_data(pred_results)
  File "E:\time_series_analize\utils\util.py", line 39, in save_data
    t = d[0], d[1], index, int(row['upper Count']), int(row['lower'], 1)
ValueError: int() base must be >= 2 and <= 36, or 0
2019-12-05 18:41:00 base.py[line:123] INFO Running job "main (trigger: cron[month='1-12', day='5', hour='18', minute='1-59', second='0'], next run at: 2019-12-05 18:42:00 CST)" (scheduled at 2019-12-05 18:41:00+08:00)
2019-12-05 18:41:01 base.py[line:131] ERROR Job "main (trigger: cron[month='1-12', day='5', hour='18', minute='1-59', second='0'], next run at: 2019-12-05 18:42:00 CST)" raised an exception
Traceback (most recent call last):
  File "E:\virtual_environment\time_series\lib\site-packages\apscheduler\executors\base.py", line 125, in run_job
    retval = job.func(*job.args, **job.kwargs)
  File "E:/time_series_analize/main.py", line 47, in main
    save_data(pred_results)
  File "E:\time_series_analize\utils\util.py", line 39, in save_data
    t = d[0], d[1], index, int(row['upper Count']), int(row['lower'], 1)
ValueError: int() base must be >= 2 and <= 36, or 0
2019-12-05 18:42:00 base.py[line:123] INFO Running job "main (trigger: cron[month='1-12', day='5', hour='18', minute='1-59', second='0'], next run at: 2019-12-05 18:43:00 CST)" (scheduled at 2019-12-05 18:42:00+08:00)
2019-12-05 18:42:01 base.py[line:131] ERROR Job "main (trigger: cron[month='1-12', day='5', hour='18', minute='1-59', second='0'], next run at: 2019-12-05 18:43:00 CST)" raised an exception
Traceback (most recent call last):
  File "E:\virtual_environment\time_series\lib\site-packages\apscheduler\executors\base.py", line 125, in run_job
    retval = job.func(*job.args, **job.kwargs)
  File "E:/time_series_analize/main.py", line 47, in main
    save_data(pred_results)
  File "E:\time_series_analize\utils\util.py", line 39, in save_data
    t = d[0], d[1], index, int(row['upper Count']), int(row['lower'], 1)
ValueError: int() base must be >= 2 and <= 36, or 0
2019-12-05 18:43:00 base.py[line:123] INFO Running job "main (trigger: cron[month='1-12', day='5', hour='18', minute='1-59', second='0'], next run at: 2019-12-05 18:44:00 CST)" (scheduled at 2019-12-05 18:43:00+08:00)
2019-12-05 18:43:01 base.py[line:131] ERROR Job "main (trigger: cron[month='1-12', day='5', hour='18', minute='1-59', second='0'], next run at: 2019-12-05 18:44:00 CST)" raised an exception
Traceback (most recent call last):
  File "E:\virtual_environment\time_series\lib\site-packages\apscheduler\executors\base.py", line 125, in run_job
    retval = job.func(*job.args, **job.kwargs)
  File "E:/time_series_analize/main.py", line 47, in main
    save_data(pred_results)
  File "E:\time_series_analize\utils\util.py", line 39, in save_data
    t = d[0], d[1], index, int(row['upper Count']), int(row['lower'], 1)
ValueError: int() base must be >= 2 and <= 36, or 0
2019-12-05 18:44:00 base.py[line:123] INFO Running job "main (trigger: cron[month='1-12', day='5', hour='18', minute='1-59', second='0'], next run at: 2019-12-05 18:45:00 CST)" (scheduled at 2019-12-05 18:44:00+08:00)
2019-12-05 18:44:01 base.py[line:131] ERROR Job "main (trigger: cron[month='1-12', day='5', hour='18', minute='1-59', second='0'], next run at: 2019-12-05 18:45:00 CST)" raised an exception
Traceback (most recent call last):
  File "E:\virtual_environment\time_series\lib\site-packages\apscheduler\executors\base.py", line 125, in run_job
    retval = job.func(*job.args, **job.kwargs)
  File "E:/time_series_analize/main.py", line 47, in main
    save_data(pred_results)
  File "E:\time_series_analize\utils\util.py", line 39, in save_data
    t = d[0], d[1], index, int(row['upper Count']), int(row['lower'], 1)
ValueError: int() base must be >= 2 and <= 36, or 0
2019-12-05 18:45:00 base.py[line:123] INFO Running job "main (trigger: cron[month='1-12', day='5', hour='18', minute='1-59', second='0'], next run at: 2019-12-05 18:46:00 CST)" (scheduled at 2019-12-05 18:45:00+08:00)
2019-12-05 18:45:01 base.py[line:131] ERROR Job "main (trigger: cron[month='1-12', day='5', hour='18', minute='1-59', second='0'], next run at: 2019-12-05 18:46:00 CST)" raised an exception
Traceback (most recent call last):
  File "E:\virtual_environment\time_series\lib\site-packages\apscheduler\executors\base.py", line 125, in run_job
    retval = job.func(*job.args, **job.kwargs)
  File "E:/time_series_analize/main.py", line 47, in main
    save_data(pred_results)
  File "E:\time_series_analize\utils\util.py", line 39, in save_data
    t = d[0], d[1], index, int(row['upper Count']), int(row['lower'], 1)
ValueError: int() base must be >= 2 and <= 36, or 0
2019-12-05 18:46:00 base.py[line:123] INFO Running job "main (trigger: cron[month='1-12', day='5', hour='18', minute='1-59', second='0'], next run at: 2019-12-05 18:47:00 CST)" (scheduled at 2019-12-05 18:46:00+08:00)
2019-12-05 18:46:01 base.py[line:131] ERROR Job "main (trigger: cron[month='1-12', day='5', hour='18', minute='1-59', second='0'], next run at: 2019-12-05 18:47:00 CST)" raised an exception
Traceback (most recent call last):
  File "E:\virtual_environment\time_series\lib\site-packages\apscheduler\executors\base.py", line 125, in run_job
    retval = job.func(*job.args, **job.kwargs)
  File "E:/time_series_analize/main.py", line 47, in main
    save_data(pred_results)
  File "E:\time_series_analize\utils\util.py", line 39, in save_data
    t = d[0], d[1], index, int(row['upper Count']), int(row['lower'], 1)
ValueError: int() base must be >= 2 and <= 36, or 0
2019-12-05 18:47:00 base.py[line:123] INFO Running job "main (trigger: cron[month='1-12', day='5', hour='18', minute='1-59', second='0'], next run at: 2019-12-05 18:48:00 CST)" (scheduled at 2019-12-05 18:47:00+08:00)
2019-12-05 18:47:01 base.py[line:131] ERROR Job "main (trigger: cron[month='1-12', day='5', hour='18', minute='1-59', second='0'], next run at: 2019-12-05 18:48:00 CST)" raised an exception
Traceback (most recent call last):
  File "E:\virtual_environment\time_series\lib\site-packages\apscheduler\executors\base.py", line 125, in run_job
    retval = job.func(*job.args, **job.kwargs)
  File "E:/time_series_analize/main.py", line 47, in main
    save_data(pred_results)
  File "E:\time_series_analize\utils\util.py", line 39, in save_data
    t = d[0], d[1], index, int(row['upper Count']), int(row['lower'], 1)
ValueError: int() base must be >= 2 and <= 36, or 0
2019-12-05 18:48:00 base.py[line:123] INFO Running job "main (trigger: cron[month='1-12', day='5', hour='18', minute='1-59', second='0'], next run at: 2019-12-05 18:49:00 CST)" (scheduled at 2019-12-05 18:48:00+08:00)
2019-12-05 18:48:01 base.py[line:131] ERROR Job "main (trigger: cron[month='1-12', day='5', hour='18', minute='1-59', second='0'], next run at: 2019-12-05 18:49:00 CST)" raised an exception
Traceback (most recent call last):
  File "E:\virtual_environment\time_series\lib\site-packages\apscheduler\executors\base.py", line 125, in run_job
    retval = job.func(*job.args, **job.kwargs)
  File "E:/time_series_analize/main.py", line 47, in main
    save_data(pred_results)
  File "E:\time_series_analize\utils\util.py", line 39, in save_data
    t = d[0], d[1], index, int(row['upper Count']), int(row['lower'], 1)
ValueError: int() base must be >= 2 and <= 36, or 0
2019-12-05 18:49:00 base.py[line:123] INFO Running job "main (trigger: cron[month='1-12', day='5', hour='18', minute='1-59', second='0'], next run at: 2019-12-05 18:50:00 CST)" (scheduled at 2019-12-05 18:49:00+08:00)
2019-12-05 18:49:01 base.py[line:131] ERROR Job "main (trigger: cron[month='1-12', day='5', hour='18', minute='1-59', second='0'], next run at: 2019-12-05 18:50:00 CST)" raised an exception
Traceback (most recent call last):
  File "E:\virtual_environment\time_series\lib\site-packages\apscheduler\executors\base.py", line 125, in run_job
    retval = job.func(*job.args, **job.kwargs)
  File "E:/time_series_analize/main.py", line 47, in main
    save_data(pred_results)
  File "E:\time_series_analize\utils\util.py", line 39, in save_data
    t = d[0], d[1], index, int(row['upper Count']), int(row['lower'], 1)
ValueError: int() base must be >= 2 and <= 36, or 0
2019-12-05 18:50:00 base.py[line:123] INFO Running job "main (trigger: cron[month='1-12', day='5', hour='18', minute='1-59', second='0'], next run at: 2019-12-05 18:51:00 CST)" (scheduled at 2019-12-05 18:50:00+08:00)
2019-12-05 18:50:01 base.py[line:131] ERROR Job "main (trigger: cron[month='1-12', day='5', hour='18', minute='1-59', second='0'], next run at: 2019-12-05 18:51:00 CST)" raised an exception
Traceback (most recent call last):
  File "E:\virtual_environment\time_series\lib\site-packages\apscheduler\executors\base.py", line 125, in run_job
    retval = job.func(*job.args, **job.kwargs)
  File "E:/time_series_analize/main.py", line 47, in main
    save_data(pred_results)
  File "E:\time_series_analize\utils\util.py", line 39, in save_data
    t = d[0], d[1], index, int(row['upper Count']), int(row['lower'], 1)
ValueError: int() base must be >= 2 and <= 36, or 0
2019-12-05 18:51:00 base.py[line:123] INFO Running job "main (trigger: cron[month='1-12', day='5', hour='18', minute='1-59', second='0'], next run at: 2019-12-05 18:52:00 CST)" (scheduled at 2019-12-05 18:51:00+08:00)
2019-12-05 18:51:01 base.py[line:131] ERROR Job "main (trigger: cron[month='1-12', day='5', hour='18', minute='1-59', second='0'], next run at: 2019-12-05 18:52:00 CST)" raised an exception
Traceback (most recent call last):
  File "E:\virtual_environment\time_series\lib\site-packages\apscheduler\executors\base.py", line 125, in run_job
    retval = job.func(*job.args, **job.kwargs)
  File "E:/time_series_analize/main.py", line 47, in main
    save_data(pred_results)
  File "E:\time_series_analize\utils\util.py", line 39, in save_data
    t = d[0], d[1], index, int(row['upper Count']), int(row['lower'], 1)
ValueError: int() base must be >= 2 and <= 36, or 0
2019-12-05 18:52:00 base.py[line:123] INFO Running job "main (trigger: cron[month='1-12', day='5', hour='18', minute='1-59', second='0'], next run at: 2019-12-05 18:53:00 CST)" (scheduled at 2019-12-05 18:52:00+08:00)
2019-12-05 18:52:01 base.py[line:131] ERROR Job "main (trigger: cron[month='1-12', day='5', hour='18', minute='1-59', second='0'], next run at: 2019-12-05 18:53:00 CST)" raised an exception
Traceback (most recent call last):
  File "E:\virtual_environment\time_series\lib\site-packages\apscheduler\executors\base.py", line 125, in run_job
    retval = job.func(*job.args, **job.kwargs)
  File "E:/time_series_analize/main.py", line 47, in main
    save_data(pred_results)
  File "E:\time_series_analize\utils\util.py", line 39, in save_data
    t = d[0], d[1], index, int(row['upper Count']), int(row['lower'], 1)
ValueError: int() base must be >= 2 and <= 36, or 0
2019-12-05 18:53:00 base.py[line:123] INFO Running job "main (trigger: cron[month='1-12', day='5', hour='18', minute='1-59', second='0'], next run at: 2019-12-05 18:54:00 CST)" (scheduled at 2019-12-05 18:53:00+08:00)
2019-12-05 18:53:01 base.py[line:131] ERROR Job "main (trigger: cron[month='1-12', day='5', hour='18', minute='1-59', second='0'], next run at: 2019-12-05 18:54:00 CST)" raised an exception
Traceback (most recent call last):
  File "E:\virtual_environment\time_series\lib\site-packages\apscheduler\executors\base.py", line 125, in run_job
    retval = job.func(*job.args, **job.kwargs)
  File "E:/time_series_analize/main.py", line 47, in main
    save_data(pred_results)
  File "E:\time_series_analize\utils\util.py", line 39, in save_data
    t = d[0], d[1], index, int(row['upper Count']), int(row['lower'], 1)
ValueError: int() base must be >= 2 and <= 36, or 0
2019-12-05 18:54:00 base.py[line:123] INFO Running job "main (trigger: cron[month='1-12', day='5', hour='18', minute='1-59', second='0'], next run at: 2019-12-05 18:55:00 CST)" (scheduled at 2019-12-05 18:54:00+08:00)
2019-12-05 18:54:01 base.py[line:131] ERROR Job "main (trigger: cron[month='1-12', day='5', hour='18', minute='1-59', second='0'], next run at: 2019-12-05 18:55:00 CST)" raised an exception
Traceback (most recent call last):
  File "E:\virtual_environment\time_series\lib\site-packages\apscheduler\executors\base.py", line 125, in run_job
    retval = job.func(*job.args, **job.kwargs)
  File "E:/time_series_analize/main.py", line 47, in main
    save_data(pred_results)
  File "E:\time_series_analize\utils\util.py", line 39, in save_data
    t = d[0], d[1], index, int(row['upper Count']), int(row['lower'], 1)
ValueError: int() base must be >= 2 and <= 36, or 0
2019-12-05 18:55:00 base.py[line:123] INFO Running job "main (trigger: cron[month='1-12', day='5', hour='18', minute='1-59', second='0'], next run at: 2019-12-05 18:56:00 CST)" (scheduled at 2019-12-05 18:55:00+08:00)
2019-12-05 18:55:01 base.py[line:131] ERROR Job "main (trigger: cron[month='1-12', day='5', hour='18', minute='1-59', second='0'], next run at: 2019-12-05 18:56:00 CST)" raised an exception
Traceback (most recent call last):
  File "E:\virtual_environment\time_series\lib\site-packages\apscheduler\executors\base.py", line 125, in run_job
    retval = job.func(*job.args, **job.kwargs)
  File "E:/time_series_analize/main.py", line 47, in main
    save_data(pred_results)
  File "E:\time_series_analize\utils\util.py", line 39, in save_data
    t = d[0], d[1], index, int(row['upper Count']), int(row['lower'], 1)
ValueError: int() base must be >= 2 and <= 36, or 0
2019-12-05 18:56:00 base.py[line:123] INFO Running job "main (trigger: cron[month='1-12', day='5', hour='18', minute='1-59', second='0'], next run at: 2019-12-05 18:57:00 CST)" (scheduled at 2019-12-05 18:56:00+08:00)
2019-12-05 18:56:01 base.py[line:131] ERROR Job "main (trigger: cron[month='1-12', day='5', hour='18', minute='1-59', second='0'], next run at: 2019-12-05 18:57:00 CST)" raised an exception
Traceback (most recent call last):
  File "E:\virtual_environment\time_series\lib\site-packages\apscheduler\executors\base.py", line 125, in run_job
    retval = job.func(*job.args, **job.kwargs)
  File "E:/time_series_analize/main.py", line 47, in main
    save_data(pred_results)
  File "E:\time_series_analize\utils\util.py", line 39, in save_data
    t = d[0], d[1], index, int(row['upper Count']), int(row['lower'], 1)
ValueError: int() base must be >= 2 and <= 36, or 0
2019-12-05 18:57:00 base.py[line:123] INFO Running job "main (trigger: cron[month='1-12', day='5', hour='18', minute='1-59', second='0'], next run at: 2019-12-05 18:58:00 CST)" (scheduled at 2019-12-05 18:57:00+08:00)
2019-12-05 18:57:01 base.py[line:131] ERROR Job "main (trigger: cron[month='1-12', day='5', hour='18', minute='1-59', second='0'], next run at: 2019-12-05 18:58:00 CST)" raised an exception
Traceback (most recent call last):
  File "E:\virtual_environment\time_series\lib\site-packages\apscheduler\executors\base.py", line 125, in run_job
    retval = job.func(*job.args, **job.kwargs)
  File "E:/time_series_analize/main.py", line 47, in main
    save_data(pred_results)
  File "E:\time_series_analize\utils\util.py", line 39, in save_data
    t = d[0], d[1], index, int(row['upper Count']), int(row['lower'], 1)
ValueError: int() base must be >= 2 and <= 36, or 0
2019-12-05 18:58:00 base.py[line:123] INFO Running job "main (trigger: cron[month='1-12', day='5', hour='18', minute='1-59', second='0'], next run at: 2019-12-05 18:59:00 CST)" (scheduled at 2019-12-05 18:58:00+08:00)
2019-12-05 18:58:01 base.py[line:131] ERROR Job "main (trigger: cron[month='1-12', day='5', hour='18', minute='1-59', second='0'], next run at: 2019-12-05 18:59:00 CST)" raised an exception
Traceback (most recent call last):
  File "E:\virtual_environment\time_series\lib\site-packages\apscheduler\executors\base.py", line 125, in run_job
    retval = job.func(*job.args, **job.kwargs)
  File "E:/time_series_analize/main.py", line 47, in main
    save_data(pred_results)
  File "E:\time_series_analize\utils\util.py", line 39, in save_data
    t = d[0], d[1], index, int(row['upper Count']), int(row['lower'], 1)
ValueError: int() base must be >= 2 and <= 36, or 0
2019-12-05 18:59:00 base.py[line:123] INFO Running job "main (trigger: cron[month='1-12', day='5', hour='18', minute='1-59', second='0'], next run at: 2020-01-05 18:01:00 CST)" (scheduled at 2019-12-05 18:59:00+08:00)
2019-12-05 18:59:01 base.py[line:131] ERROR Job "main (trigger: cron[month='1-12', day='5', hour='18', minute='1-59', second='0'], next run at: 2020-01-05 18:01:00 CST)" raised an exception
Traceback (most recent call last):
  File "E:\virtual_environment\time_series\lib\site-packages\apscheduler\executors\base.py", line 125, in run_job
    retval = job.func(*job.args, **job.kwargs)
  File "E:/time_series_analize/main.py", line 47, in main
    save_data(pred_results)
  File "E:\time_series_analize\utils\util.py", line 39, in save_data
    t = d[0], d[1], index, int(row['upper Count']), int(row['lower'], 1)
ValueError: int() base must be >= 2 and <= 36, or 0
2019-12-06 08:59:55 base.py[line:440] INFO Adding job tentatively -- it will be properly scheduled when the scheduler starts
2019-12-06 08:59:55 base.py[line:881] INFO Added job "main" to job store "default"
2019-12-06 08:59:55 base.py[line:166] INFO Scheduler started
2019-12-06 09:00:00 base.py[line:123] INFO Running job "main (trigger: cron[month='1-12', day='6', hour='8-9', minute='0-59', second='0'], next run at: 2019-12-06 09:00:00 CST)" (scheduled at 2019-12-06 09:00:00+08:00)
2019-12-06 09:00:01 base.py[line:131] ERROR Job "main (trigger: cron[month='1-12', day='6', hour='8-9', minute='0-59', second='0'], next run at: 2019-12-06 09:01:00 CST)" raised an exception
Traceback (most recent call last):
  File "E:\virtual_environment\time_series\lib\site-packages\apscheduler\executors\base.py", line 125, in run_job
    retval = job.func(*job.args, **job.kwargs)
  File "E:/time_series_analize/main.py", line 47, in main
    save_data(pred_results)
  File "E:\time_series_analize\utils\util.py", line 39, in save_data
    t = d[0], d[1], index, int(row['upper Count']), int(row['lower'], 1)
ValueError: int() base must be >= 2 and <= 36, or 0
2019-12-06 09:01:00 base.py[line:123] INFO Running job "main (trigger: cron[month='1-12', day='6', hour='8-9', minute='0-59', second='0'], next run at: 2019-12-06 09:02:00 CST)" (scheduled at 2019-12-06 09:01:00+08:00)
2019-12-06 09:01:01 base.py[line:131] ERROR Job "main (trigger: cron[month='1-12', day='6', hour='8-9', minute='0-59', second='0'], next run at: 2019-12-06 09:02:00 CST)" raised an exception
Traceback (most recent call last):
  File "E:\virtual_environment\time_series\lib\site-packages\apscheduler\executors\base.py", line 125, in run_job
    retval = job.func(*job.args, **job.kwargs)
  File "E:/time_series_analize/main.py", line 47, in main
    save_data(pred_results)
  File "E:\time_series_analize\utils\util.py", line 39, in save_data
    t = d[0], d[1], index, int(row['upper Count']), int(row['lower'], 1)
ValueError: int() base must be >= 2 and <= 36, or 0
2019-12-06 09:02:46 base.py[line:440] INFO Adding job tentatively -- it will be properly scheduled when the scheduler starts
2019-12-06 09:02:46 base.py[line:881] INFO Added job "main" to job store "default"
2019-12-06 09:02:46 base.py[line:166] INFO Scheduler started
2019-12-06 09:03:00 base.py[line:123] INFO Running job "main (trigger: cron[month='1-12', day='6', hour='8-9', minute='0-59', second='0'], next run at: 2019-12-06 09:03:00 CST)" (scheduled at 2019-12-06 09:03:00+08:00)
2019-12-06 09:03:01 base.py[line:144] INFO Job "main (trigger: cron[month='1-12', day='6', hour='8-9', minute='0-59', second='0'], next run at: 2019-12-06 09:04:00 CST)" executed successfully
2019-12-06 09:04:00 base.py[line:123] INFO Running job "main (trigger: cron[month='1-12', day='6', hour='8-9', minute='0-59', second='0'], next run at: 2019-12-06 09:05:00 CST)" (scheduled at 2019-12-06 09:04:00+08:00)
2019-12-06 09:04:01 base.py[line:144] INFO Job "main (trigger: cron[month='1-12', day='6', hour='8-9', minute='0-59', second='0'], next run at: 2019-12-06 09:05:00 CST)" executed successfully
2019-12-06 09:04:41 base.py[line:440] INFO Adding job tentatively -- it will be properly scheduled when the scheduler starts
2019-12-06 09:04:41 base.py[line:881] INFO Added job "main" to job store "default"
2019-12-06 09:04:41 base.py[line:166] INFO Scheduler started
2019-12-06 09:05:00 base.py[line:123] INFO Running job "main (trigger: cron[month='1-12', day='6', hour='8-9', minute='0-59', second='0'], next run at: 2019-12-06 09:05:00 CST)" (scheduled at 2019-12-06 09:05:00+08:00)
2019-12-06 09:05:01 base.py[line:144] INFO Job "main (trigger: cron[month='1-12', day='6', hour='8-9', minute='0-59', second='0'], next run at: 2019-12-06 09:06:00 CST)" executed successfully
2019-12-06 09:06:30 base.py[line:440] INFO Adding job tentatively -- it will be properly scheduled when the scheduler starts
2019-12-06 09:06:30 base.py[line:881] INFO Added job "main" to job store "default"
2019-12-06 09:06:30 base.py[line:166] INFO Scheduler started
2019-12-12 10:52:44 base.py[line:440] INFO Adding job tentatively -- it will be properly scheduled when the scheduler starts
2019-12-12 10:52:44 base.py[line:881] INFO Added job "main" to job store "default"
2019-12-12 10:52:44 base.py[line:166] INFO Scheduler started
the task run successful!2019-12-12 11:15:48 base.py[line:440] INFO Adding job tentatively -- it will be properly scheduled when the scheduler starts
2019-12-12 11:15:48 base.py[line:881] INFO Added job "main" to job store "default"
2019-12-12 11:15:48 base.py[line:166] INFO Scheduler started
2019-12-12 11:16:00 base.py[line:123] INFO Running job "main (trigger: cron[month='1-12', day='12', hour='11', minute='0-59', second='0'], next run at: 2019-12-12 11:16:00 CST)" (scheduled at 2019-12-12 11:16:00+08:00)
2019-12-12 11:16:02 base.py[line:144] INFO Job "main (trigger: cron[month='1-12', day='12', hour='11', minute='0-59', second='0'], next run at: 2019-12-12 11:17:00 CST)" executed successfully
2019-12-12 11:17:00 base.py[line:123] INFO Running job "main (trigger: cron[month='1-12', day='12', hour='11', minute='0-59', second='0'], next run at: 2019-12-12 11:18:00 CST)" (scheduled at 2019-12-12 11:17:00+08:00)
2019-12-12 11:17:01 base.py[line:144] INFO Job "main (trigger: cron[month='1-12', day='12', hour='11', minute='0-59', second='0'], next run at: 2019-12-12 11:18:00 CST)" executed successfully
2019-12-12 11:27:35 base.py[line:440] INFO Adding job tentatively -- it will be properly scheduled when the scheduler starts
2019-12-12 11:27:35 base.py[line:881] INFO Added job "main" to job store "default"
2019-12-12 11:27:35 base.py[line:166] INFO Scheduler started
2019-12-12 11:28:00 base.py[line:123] INFO Running job "main (trigger: cron[month='1-12', day='12', hour='11', minute='0-59', second='0'], next run at: 2019-12-12 11:28:00 CST)" (scheduled at 2019-12-12 11:28:00+08:00)
2019-12-12 11:28:01 base.py[line:144] INFO Job "main (trigger: cron[month='1-12', day='12', hour='11', minute='0-59', second='0'], next run at: 2019-12-12 11:29:00 CST)" executed successfully
2019-12-12 11:29:00 base.py[line:123] INFO Running job "main (trigger: cron[month='1-12', day='12', hour='11', minute='0-59', second='0'], next run at: 2019-12-12 11:30:00 CST)" (scheduled at 2019-12-12 11:29:00+08:00)
2019-12-12 11:29:01 base.py[line:144] INFO Job "main (trigger: cron[month='1-12', day='12', hour='11', minute='0-59', second='0'], next run at: 2019-12-12 11:30:00 CST)" executed successfully
2019-12-12 11:30:00 base.py[line:123] INFO Running job "main (trigger: cron[month='1-12', day='12', hour='11', minute='0-59', second='0'], next run at: 2019-12-12 11:31:00 CST)" (scheduled at 2019-12-12 11:30:00+08:00)
2019-12-12 11:30:01 base.py[line:144] INFO Job "main (trigger: cron[month='1-12', day='12', hour='11', minute='0-59', second='0'], next run at: 2019-12-12 11:31:00 CST)" executed successfully
2019-12-12 11:30:22 base.py[line:440] INFO Adding job tentatively -- it will be properly scheduled when the scheduler starts
2019-12-12 11:30:22 base.py[line:881] INFO Added job "main" to job store "default"
2019-12-12 11:30:22 base.py[line:166] INFO Scheduler started
2019-12-12 11:31:00 base.py[line:123] INFO Running job "main (trigger: cron[month='1-12', day='12', hour='11', minute='0-59', second='0'], next run at: 2019-12-12 11:31:00 CST)" (scheduled at 2019-12-12 11:31:00+08:00)
2019-12-12 11:31:01 base.py[line:144] INFO Job "main (trigger: cron[month='1-12', day='12', hour='11', minute='0-59', second='0'], next run at: 2019-12-12 11:32:00 CST)" executed successfully
2019-12-12 11:32:00 base.py[line:123] INFO Running job "main (trigger: cron[month='1-12', day='12', hour='11', minute='0-59', second='0'], next run at: 2019-12-12 11:33:00 CST)" (scheduled at 2019-12-12 11:32:00+08:00)
2019-12-12 11:32:01 base.py[line:144] INFO Job "main (trigger: cron[month='1-12', day='12', hour='11', minute='0-59', second='0'], next run at: 2019-12-12 11:33:00 CST)" executed successfully
2019-12-12 11:33:00 base.py[line:123] INFO Running job "main (trigger: cron[month='1-12', day='12', hour='11', minute='0-59', second='0'], next run at: 2019-12-12 11:34:00 CST)" (scheduled at 2019-12-12 11:33:00+08:00)
2019-12-12 11:33:01 base.py[line:144] INFO Job "main (trigger: cron[month='1-12', day='12', hour='11', minute='0-59', second='0'], next run at: 2019-12-12 11:34:00 CST)" executed successfully
2019-12-12 11:34:00 base.py[line:123] INFO Running job "main (trigger: cron[month='1-12', day='12', hour='11', minute='0-59', second='0'], next run at: 2019-12-12 11:35:00 CST)" (scheduled at 2019-12-12 11:34:00+08:00)
2019-12-12 11:34:01 base.py[line:144] INFO Job "main (trigger: cron[month='1-12', day='12', hour='11', minute='0-59', second='0'], next run at: 2019-12-12 11:35:00 CST)" executed successfully
2019-12-12 11:35:00 base.py[line:123] INFO Running job "main (trigger: cron[month='1-12', day='12', hour='11', minute='0-59', second='0'], next run at: 2019-12-12 11:36:00 CST)" (scheduled at 2019-12-12 11:35:00+08:00)
2019-12-12 11:35:01 base.py[line:144] INFO Job "main (trigger: cron[month='1-12', day='12', hour='11', minute='0-59', second='0'], next run at: 2019-12-12 11:36:00 CST)" executed successfully
2019-12-12 11:36:00 base.py[line:123] INFO Running job "main (trigger: cron[month='1-12', day='12', hour='11', minute='0-59', second='0'], next run at: 2019-12-12 11:37:00 CST)" (scheduled at 2019-12-12 11:36:00+08:00)
2019-12-12 11:36:01 base.py[line:144] INFO Job "main (trigger: cron[month='1-12', day='12', hour='11', minute='0-59', second='0'], next run at: 2019-12-12 11:37:00 CST)" executed successfully
2019-12-12 11:45:35 base.py[line:440] INFO Adding job tentatively -- it will be properly scheduled when the scheduler starts
2019-12-12 11:45:35 base.py[line:881] INFO Added job "main" to job store "default"
2019-12-12 11:45:35 base.py[line:166] INFO Scheduler started
2019-12-12 11:46:00 base.py[line:123] INFO Running job "main (trigger: cron[month='1-12', day='12', hour='11', minute='0-59', second='0'], next run at: 2019-12-12 11:46:00 CST)" (scheduled at 2019-12-12 11:46:00+08:00)
2019-12-12 11:46:01 base.py[line:144] INFO Job "main (trigger: cron[month='1-12', day='12', hour='11', minute='0-59', second='0'], next run at: 2019-12-12 11:47:00 CST)" executed successfully
2019-12-12 11:47:00 base.py[line:123] INFO Running job "main (trigger: cron[month='1-12', day='12', hour='11', minute='0-59', second='0'], next run at: 2019-12-12 11:48:00 CST)" (scheduled at 2019-12-12 11:47:00+08:00)
2019-12-12 11:47:01 base.py[line:144] INFO Job "main (trigger: cron[month='1-12', day='12', hour='11', minute='0-59', second='0'], next run at: 2019-12-12 11:48:00 CST)" executed successfully
2019-12-12 11:48:00 base.py[line:123] INFO Running job "main (trigger: cron[month='1-12', day='12', hour='11', minute='0-59', second='0'], next run at: 2019-12-12 11:49:00 CST)" (scheduled at 2019-12-12 11:48:00+08:00)
2019-12-12 11:48:01 base.py[line:144] INFO Job "main (trigger: cron[month='1-12', day='12', hour='11', minute='0-59', second='0'], next run at: 2019-12-12 11:49:00 CST)" executed successfully
2019-12-12 11:49:00 base.py[line:123] INFO Running job "main (trigger: cron[month='1-12', day='12', hour='11', minute='0-59', second='0'], next run at: 2019-12-12 11:50:00 CST)" (scheduled at 2019-12-12 11:49:00+08:00)
2019-12-12 11:49:01 base.py[line:144] INFO Job "main (trigger: cron[month='1-12', day='12', hour='11', minute='0-59', second='0'], next run at: 2019-12-12 11:50:00 CST)" executed successfully
2019-12-12 11:50:00 base.py[line:123] INFO Running job "main (trigger: cron[month='1-12', day='12', hour='11', minute='0-59', second='0'], next run at: 2019-12-12 11:51:00 CST)" (scheduled at 2019-12-12 11:50:00+08:00)
2019-12-12 11:50:01 base.py[line:144] INFO Job "main (trigger: cron[month='1-12', day='12', hour='11', minute='0-59', second='0'], next run at: 2019-12-12 11:51:00 CST)" executed successfully
2019-12-12 11:51:00 base.py[line:123] INFO Running job "main (trigger: cron[month='1-12', day='12', hour='11', minute='0-59', second='0'], next run at: 2019-12-12 11:52:00 CST)" (scheduled at 2019-12-12 11:51:00+08:00)
2019-12-12 11:51:01 base.py[line:144] INFO Job "main (trigger: cron[month='1-12', day='12', hour='11', minute='0-59', second='0'], next run at: 2019-12-12 11:52:00 CST)" executed successfully
2019-12-12 11:52:00 base.py[line:123] INFO Running job "main (trigger: cron[month='1-12', day='12', hour='11', minute='0-59', second='0'], next run at: 2019-12-12 11:53:00 CST)" (scheduled at 2019-12-12 11:52:00+08:00)
2019-12-12 11:52:01 base.py[line:144] INFO Job "main (trigger: cron[month='1-12', day='12', hour='11', minute='0-59', second='0'], next run at: 2019-12-12 11:53:00 CST)" executed successfully
2019-12-12 11:53:00 base.py[line:123] INFO Running job "main (trigger: cron[month='1-12', day='12', hour='11', minute='0-59', second='0'], next run at: 2019-12-12 11:54:00 CST)" (scheduled at 2019-12-12 11:53:00+08:00)
2019-12-12 11:53:01 base.py[line:144] INFO Job "main (trigger: cron[month='1-12', day='12', hour='11', minute='0-59', second='0'], next run at: 2019-12-12 11:54:00 CST)" executed successfully
2019-12-12 11:54:00 base.py[line:123] INFO Running job "main (trigger: cron[month='1-12', day='12', hour='11', minute='0-59', second='0'], next run at: 2019-12-12 11:55:00 CST)" (scheduled at 2019-12-12 11:54:00+08:00)
2019-12-12 11:54:01 base.py[line:144] INFO Job "main (trigger: cron[month='1-12', day='12', hour='11', minute='0-59', second='0'], next run at: 2019-12-12 11:55:00 CST)" executed successfully
2019-12-12 11:56:29 base.py[line:440] INFO Adding job tentatively -- it will be properly scheduled when the scheduler starts
2019-12-12 11:56:29 base.py[line:881] INFO Added job "main" to job store "default"
2019-12-12 11:56:29 base.py[line:166] INFO Scheduler started
2019-12-12 11:57:00 base.py[line:123] INFO Running job "main (trigger: cron[month='1-12', day='12', hour='11', minute='0-59', second='0'], next run at: 2019-12-12 11:57:00 CST)" (scheduled at 2019-12-12 11:57:00+08:00)
2019-12-12 11:57:01 base.py[line:144] INFO Job "main (trigger: cron[month='1-12', day='12', hour='11', minute='0-59', second='0'], next run at: 2019-12-12 11:58:00 CST)" executed successfully
2019-12-12 11:58:00 base.py[line:123] INFO Running job "main (trigger: cron[month='1-12', day='12', hour='11', minute='0-59', second='0'], next run at: 2019-12-12 11:59:00 CST)" (scheduled at 2019-12-12 11:58:00+08:00)
2019-12-12 11:58:01 base.py[line:144] INFO Job "main (trigger: cron[month='1-12', day='12', hour='11', minute='0-59', second='0'], next run at: 2019-12-12 11:59:00 CST)" executed successfully
2019-12-12 16:00:51 base.py[line:440] INFO Adding job tentatively -- it will be properly scheduled when the scheduler starts
2019-12-12 16:00:51 base.py[line:881] INFO Added job "main" to job store "default"
2019-12-12 16:00:51 base.py[line:166] INFO Scheduler started
2019-12-12 16:01:00 base.py[line:123] INFO Running job "main (trigger: cron[month='1-12', day='12', hour='16', minute='0-59', second='0'], next run at: 2019-12-12 16:01:00 CST)" (scheduled at 2019-12-12 16:01:00+08:00)
2019-12-12 16:01:01 base.py[line:131] ERROR Job "main (trigger: cron[month='1-12', day='12', hour='16', minute='0-59', second='0'], next run at: 2019-12-12 16:02:00 CST)" raised an exception
Traceback (most recent call last):
  File "E:\virtual_environment\time_series\lib\site-packages\apscheduler\executors\base.py", line 125, in run_job
    retval = job.func(*job.args, **job.kwargs)
  File "E:/time_series_analize/main.py", line 47, in main
    save_data(pred_results)
  File "E:\time_series_analize\utils\util.py", line 46, in save_data
    mc.add(sql, ls)
  File "E:\time_series_analize\baseClass\baseMysql.py", line 15, in add
    effect_rows = self.cursor.executemany(sql, T)
  File "E:\virtual_environment\time_series\lib\site-packages\pymysql\cursors.py", line 199, in executemany
    self.rowcount = sum(self.execute(query, arg) for arg in args)
  File "E:\virtual_environment\time_series\lib\site-packages\pymysql\cursors.py", line 199, in <genexpr>
    self.rowcount = sum(self.execute(query, arg) for arg in args)
  File "E:\virtual_environment\time_series\lib\site-packages\pymysql\cursors.py", line 170, in execute
    result = self._query(query)
  File "E:\virtual_environment\time_series\lib\site-packages\pymysql\cursors.py", line 328, in _query
    conn.query(q)
  File "E:\virtual_environment\time_series\lib\site-packages\pymysql\connections.py", line 517, in query
    self._affected_rows = self._read_query_result(unbuffered=unbuffered)
  File "E:\virtual_environment\time_series\lib\site-packages\pymysql\connections.py", line 732, in _read_query_result
    result.read()
  File "E:\virtual_environment\time_series\lib\site-packages\pymysql\connections.py", line 1075, in read
    first_packet = self.connection._read_packet()
  File "E:\virtual_environment\time_series\lib\site-packages\pymysql\connections.py", line 684, in _read_packet
    packet.check_error()
  File "E:\virtual_environment\time_series\lib\site-packages\pymysql\protocol.py", line 220, in check_error
    err.raise_mysql_exception(self._data)
  File "E:\virtual_environment\time_series\lib\site-packages\pymysql\err.py", line 109, in raise_mysql_exception
    raise errorclass(errno, errval)
pymysql.err.ProgrammingError: (1064, "You have an error in your SQL syntax; check the manual that corresponds to your MySQL server version for the right syntax to use near '' at line 4")
2019-12-12 16:02:04 base.py[line:440] INFO Adding job tentatively -- it will be properly scheduled when the scheduler starts
2019-12-12 16:02:04 base.py[line:881] INFO Added job "main" to job store "default"
2019-12-12 16:02:04 base.py[line:166] INFO Scheduler started
2019-12-12 16:03:00 base.py[line:123] INFO Running job "main (trigger: cron[month='1-12', day='12', hour='16', minute='0-59', second='0'], next run at: 2019-12-12 16:03:00 CST)" (scheduled at 2019-12-12 16:03:00+08:00)
2019-12-12 16:03:01 base.py[line:131] ERROR Job "main (trigger: cron[month='1-12', day='12', hour='16', minute='0-59', second='0'], next run at: 2019-12-12 16:04:00 CST)" raised an exception
Traceback (most recent call last):
  File "E:\virtual_environment\time_series\lib\site-packages\apscheduler\executors\base.py", line 125, in run_job
    retval = job.func(*job.args, **job.kwargs)
  File "E:/time_series_analize/main.py", line 47, in main
    save_data(pred_results)
  File "E:\time_series_analize\utils\util.py", line 46, in save_data
    mc.add(sql, ls)
  File "E:\time_series_analize\baseClass\baseMysql.py", line 15, in add
    print(sql)
  File "E:\virtual_environment\time_series\lib\site-packages\pymysql\cursors.py", line 199, in executemany
    self.rowcount = sum(self.execute(query, arg) for arg in args)
  File "E:\virtual_environment\time_series\lib\site-packages\pymysql\cursors.py", line 199, in <genexpr>
    self.rowcount = sum(self.execute(query, arg) for arg in args)
  File "E:\virtual_environment\time_series\lib\site-packages\pymysql\cursors.py", line 170, in execute
    result = self._query(query)
  File "E:\virtual_environment\time_series\lib\site-packages\pymysql\cursors.py", line 328, in _query
    conn.query(q)
  File "E:\virtual_environment\time_series\lib\site-packages\pymysql\connections.py", line 517, in query
    self._affected_rows = self._read_query_result(unbuffered=unbuffered)
  File "E:\virtual_environment\time_series\lib\site-packages\pymysql\connections.py", line 732, in _read_query_result
    result.read()
  File "E:\virtual_environment\time_series\lib\site-packages\pymysql\connections.py", line 1075, in read
    first_packet = self.connection._read_packet()
  File "E:\virtual_environment\time_series\lib\site-packages\pymysql\connections.py", line 684, in _read_packet
    packet.check_error()
  File "E:\virtual_environment\time_series\lib\site-packages\pymysql\protocol.py", line 220, in check_error
    err.raise_mysql_exception(self._data)
  File "E:\virtual_environment\time_series\lib\site-packages\pymysql\err.py", line 109, in raise_mysql_exception
    raise errorclass(errno, errval)
pymysql.err.ProgrammingError: (1064, "You have an error in your SQL syntax; check the manual that corresponds to your MySQL server version for the right syntax to use near '' at line 4")
2019-12-12 16:03:09 base.py[line:440] INFO Adding job tentatively -- it will be properly scheduled when the scheduler starts
2019-12-12 16:03:09 base.py[line:881] INFO Added job "main" to job store "default"
2019-12-12 16:03:09 base.py[line:166] INFO Scheduler started
2019-12-12 16:04:00 base.py[line:123] INFO Running job "main (trigger: cron[month='1-12', day='12', hour='16', minute='0-59', second='0'], next run at: 2019-12-12 16:04:00 CST)" (scheduled at 2019-12-12 16:04:00+08:00)
2019-12-12 16:04:01 base.py[line:144] INFO Job "main (trigger: cron[month='1-12', day='12', hour='16', minute='0-59', second='0'], next run at: 2019-12-12 16:05:00 CST)" executed successfully
2019-12-12 16:05:00 base.py[line:123] INFO Running job "main (trigger: cron[month='1-12', day='12', hour='16', minute='0-59', second='0'], next run at: 2019-12-12 16:06:00 CST)" (scheduled at 2019-12-12 16:05:00+08:00)
2019-12-12 16:05:01 base.py[line:144] INFO Job "main (trigger: cron[month='1-12', day='12', hour='16', minute='0-59', second='0'], next run at: 2019-12-12 16:06:00 CST)" executed successfully
2019-12-12 16:06:00 base.py[line:123] INFO Running job "main (trigger: cron[month='1-12', day='12', hour='16', minute='0-59', second='0'], next run at: 2019-12-12 16:07:00 CST)" (scheduled at 2019-12-12 16:06:00+08:00)
2019-12-12 16:06:01 base.py[line:144] INFO Job "main (trigger: cron[month='1-12', day='12', hour='16', minute='0-59', second='0'], next run at: 2019-12-12 16:07:00 CST)" executed successfully
2019-12-12 16:07:00 base.py[line:123] INFO Running job "main (trigger: cron[month='1-12', day='12', hour='16', minute='0-59', second='0'], next run at: 2019-12-12 16:08:00 CST)" (scheduled at 2019-12-12 16:07:00+08:00)
2019-12-12 16:07:01 base.py[line:144] INFO Job "main (trigger: cron[month='1-12', day='12', hour='16', minute='0-59', second='0'], next run at: 2019-12-12 16:08:00 CST)" executed successfully
2019-12-12 16:08:00 base.py[line:123] INFO Running job "main (trigger: cron[month='1-12', day='12', hour='16', minute='0-59', second='0'], next run at: 2019-12-12 16:09:00 CST)" (scheduled at 2019-12-12 16:08:00+08:00)
2019-12-12 16:08:01 base.py[line:144] INFO Job "main (trigger: cron[month='1-12', day='12', hour='16', minute='0-59', second='0'], next run at: 2019-12-12 16:09:00 CST)" executed successfully
2019-12-12 16:09:00 base.py[line:123] INFO Running job "main (trigger: cron[month='1-12', day='12', hour='16', minute='0-59', second='0'], next run at: 2019-12-12 16:10:00 CST)" (scheduled at 2019-12-12 16:09:00+08:00)
2019-12-12 16:09:01 base.py[line:144] INFO Job "main (trigger: cron[month='1-12', day='12', hour='16', minute='0-59', second='0'], next run at: 2019-12-12 16:10:00 CST)" executed successfully
2019-12-12 16:10:00 base.py[line:123] INFO Running job "main (trigger: cron[month='1-12', day='12', hour='16', minute='0-59', second='0'], next run at: 2019-12-12 16:11:00 CST)" (scheduled at 2019-12-12 16:10:00+08:00)
2019-12-12 16:10:01 base.py[line:144] INFO Job "main (trigger: cron[month='1-12', day='12', hour='16', minute='0-59', second='0'], next run at: 2019-12-12 16:11:00 CST)" executed successfully
2019-12-12 16:11:00 base.py[line:123] INFO Running job "main (trigger: cron[month='1-12', day='12', hour='16', minute='0-59', second='0'], next run at: 2019-12-12 16:12:00 CST)" (scheduled at 2019-12-12 16:11:00+08:00)
2019-12-12 16:11:01 base.py[line:144] INFO Job "main (trigger: cron[month='1-12', day='12', hour='16', minute='0-59', second='0'], next run at: 2019-12-12 16:12:00 CST)" executed successfully
2019-12-12 16:12:00 base.py[line:123] INFO Running job "main (trigger: cron[month='1-12', day='12', hour='16', minute='0-59', second='0'], next run at: 2019-12-12 16:13:00 CST)" (scheduled at 2019-12-12 16:12:00+08:00)
2019-12-12 16:12:01 base.py[line:144] INFO Job "main (trigger: cron[month='1-12', day='12', hour='16', minute='0-59', second='0'], next run at: 2019-12-12 16:13:00 CST)" executed successfully
2019-12-12 16:13:00 base.py[line:123] INFO Running job "main (trigger: cron[month='1-12', day='12', hour='16', minute='0-59', second='0'], next run at: 2019-12-12 16:14:00 CST)" (scheduled at 2019-12-12 16:13:00+08:00)
2019-12-12 16:13:01 base.py[line:144] INFO Job "main (trigger: cron[month='1-12', day='12', hour='16', minute='0-59', second='0'], next run at: 2019-12-12 16:14:00 CST)" executed successfully
2019-12-12 16:14:00 base.py[line:123] INFO Running job "main (trigger: cron[month='1-12', day='12', hour='16', minute='0-59', second='0'], next run at: 2019-12-12 16:15:00 CST)" (scheduled at 2019-12-12 16:14:00+08:00)
2019-12-12 16:14:01 base.py[line:144] INFO Job "main (trigger: cron[month='1-12', day='12', hour='16', minute='0-59', second='0'], next run at: 2019-12-12 16:15:00 CST)" executed successfully
2019-12-12 16:15:00 base.py[line:123] INFO Running job "main (trigger: cron[month='1-12', day='12', hour='16', minute='0-59', second='0'], next run at: 2019-12-12 16:16:00 CST)" (scheduled at 2019-12-12 16:15:00+08:00)
2019-12-12 16:15:01 base.py[line:144] INFO Job "main (trigger: cron[month='1-12', day='12', hour='16', minute='0-59', second='0'], next run at: 2019-12-12 16:16:00 CST)" executed successfully
2019-12-12 16:16:00 base.py[line:123] INFO Running job "main (trigger: cron[month='1-12', day='12', hour='16', minute='0-59', second='0'], next run at: 2019-12-12 16:17:00 CST)" (scheduled at 2019-12-12 16:16:00+08:00)
2019-12-12 16:16:01 base.py[line:144] INFO Job "main (trigger: cron[month='1-12', day='12', hour='16', minute='0-59', second='0'], next run at: 2019-12-12 16:17:00 CST)" executed successfully
2019-12-12 16:17:00 base.py[line:123] INFO Running job "main (trigger: cron[month='1-12', day='12', hour='16', minute='0-59', second='0'], next run at: 2019-12-12 16:18:00 CST)" (scheduled at 2019-12-12 16:17:00+08:00)
2019-12-12 16:17:01 base.py[line:144] INFO Job "main (trigger: cron[month='1-12', day='12', hour='16', minute='0-59', second='0'], next run at: 2019-12-12 16:18:00 CST)" executed successfully
2019-12-12 16:18:00 base.py[line:123] INFO Running job "main (trigger: cron[month='1-12', day='12', hour='16', minute='0-59', second='0'], next run at: 2019-12-12 16:19:00 CST)" (scheduled at 2019-12-12 16:18:00+08:00)
2019-12-12 16:18:01 base.py[line:144] INFO Job "main (trigger: cron[month='1-12', day='12', hour='16', minute='0-59', second='0'], next run at: 2019-12-12 16:19:00 CST)" executed successfully
2019-12-12 16:19:00 base.py[line:123] INFO Running job "main (trigger: cron[month='1-12', day='12', hour='16', minute='0-59', second='0'], next run at: 2019-12-12 16:20:00 CST)" (scheduled at 2019-12-12 16:19:00+08:00)
2019-12-12 16:19:01 base.py[line:144] INFO Job "main (trigger: cron[month='1-12', day='12', hour='16', minute='0-59', second='0'], next run at: 2019-12-12 16:20:00 CST)" executed successfully
2019-12-12 16:20:00 base.py[line:123] INFO Running job "main (trigger: cron[month='1-12', day='12', hour='16', minute='0-59', second='0'], next run at: 2019-12-12 16:21:00 CST)" (scheduled at 2019-12-12 16:20:00+08:00)
2019-12-12 16:20:01 base.py[line:144] INFO Job "main (trigger: cron[month='1-12', day='12', hour='16', minute='0-59', second='0'], next run at: 2019-12-12 16:21:00 CST)" executed successfully
2019-12-12 16:21:00 base.py[line:123] INFO Running job "main (trigger: cron[month='1-12', day='12', hour='16', minute='0-59', second='0'], next run at: 2019-12-12 16:22:00 CST)" (scheduled at 2019-12-12 16:21:00+08:00)
2019-12-12 16:21:00 base.py[line:440] INFO Adding job tentatively -- it will be properly scheduled when the scheduler starts
2019-12-12 16:21:00 base.py[line:881] INFO Added job "main" to job store "default"
2019-12-12 16:21:00 base.py[line:166] INFO Scheduler started
2019-12-12 16:21:01 base.py[line:144] INFO Job "main (trigger: cron[month='1-12', day='12', hour='16', minute='0-59', second='0'], next run at: 2019-12-12 16:22:00 CST)" executed successfully
2019-12-12 16:22:00 base.py[line:123] INFO Running job "main (trigger: cron[month='1-12', day='12', hour='16', minute='0-59', second='0'], next run at: 2019-12-12 16:22:00 CST)" (scheduled at 2019-12-12 16:22:00+08:00)
2019-12-12 16:22:00 base.py[line:123] INFO Running job "main (trigger: cron[month='1-12', day='12', hour='16', minute='0-59', second='0'], next run at: 2019-12-12 16:23:00 CST)" (scheduled at 2019-12-12 16:22:00+08:00)
2019-12-12 16:22:01 base.py[line:131] ERROR Job "main (trigger: cron[month='1-12', day='12', hour='16', minute='0-59', second='0'], next run at: 2019-12-12 16:23:00 CST)" raised an exception
Traceback (most recent call last):
  File "E:\virtual_environment\time_series\lib\site-packages\apscheduler\executors\base.py", line 125, in run_job
    retval = job.func(*job.args, **job.kwargs)
  File "E:/time_series_analize/main.py", line 47, in main
    save_data(pred_results)
  File "E:\time_series_analize\utils\util.py", line 49, in save_data
    mc.add(sql, ls)
  File "E:\time_series_analize\baseClass\baseMysql.py", line 17, in add
    effect_rows = self.cursor.executemany(sql, T)
  File "E:\virtual_environment\time_series\lib\site-packages\pymysql\cursors.py", line 199, in executemany
    self.rowcount = sum(self.execute(query, arg) for arg in args)
  File "E:\virtual_environment\time_series\lib\site-packages\pymysql\cursors.py", line 199, in <genexpr>
    self.rowcount = sum(self.execute(query, arg) for arg in args)
  File "E:\virtual_environment\time_series\lib\site-packages\pymysql\cursors.py", line 170, in execute
    result = self._query(query)
  File "E:\virtual_environment\time_series\lib\site-packages\pymysql\cursors.py", line 328, in _query
    conn.query(q)
  File "E:\virtual_environment\time_series\lib\site-packages\pymysql\connections.py", line 517, in query
    self._affected_rows = self._read_query_result(unbuffered=unbuffered)
  File "E:\virtual_environment\time_series\lib\site-packages\pymysql\connections.py", line 732, in _read_query_result
    result.read()
  File "E:\virtual_environment\time_series\lib\site-packages\pymysql\connections.py", line 1075, in read
    first_packet = self.connection._read_packet()
  File "E:\virtual_environment\time_series\lib\site-packages\pymysql\connections.py", line 684, in _read_packet
    packet.check_error()
  File "E:\virtual_environment\time_series\lib\site-packages\pymysql\protocol.py", line 220, in check_error
    err.raise_mysql_exception(self._data)
  File "E:\virtual_environment\time_series\lib\site-packages\pymysql\err.py", line 109, in raise_mysql_exception
    raise errorclass(errno, errval)
pymysql.err.InternalError: (1411, "Incorrect datetime value: '2019.12.12 16:22:01 ' for function str_to_date")
2019-12-12 16:22:01 base.py[line:144] INFO Job "main (trigger: cron[month='1-12', day='12', hour='16', minute='0-59', second='0'], next run at: 2019-12-12 16:23:00 CST)" executed successfully
2019-12-12 16:22:56 base.py[line:440] INFO Adding job tentatively -- it will be properly scheduled when the scheduler starts
2019-12-12 16:22:56 base.py[line:881] INFO Added job "main" to job store "default"
2019-12-12 16:22:56 base.py[line:166] INFO Scheduler started
2019-12-12 16:23:00 base.py[line:123] INFO Running job "main (trigger: cron[month='1-12', day='12', hour='16', minute='0-59', second='0'], next run at: 2019-12-12 16:23:00 CST)" (scheduled at 2019-12-12 16:23:00+08:00)
2019-12-12 16:23:01 base.py[line:131] ERROR Job "main (trigger: cron[month='1-12', day='12', hour='16', minute='0-59', second='0'], next run at: 2019-12-12 16:24:00 CST)" raised an exception
Traceback (most recent call last):
  File "E:\virtual_environment\time_series\lib\site-packages\apscheduler\executors\base.py", line 125, in run_job
    retval = job.func(*job.args, **job.kwargs)
  File "E:/time_series_analize/main.py", line 47, in main
    save_data(pred_results)
  File "E:\time_series_analize\utils\util.py", line 49, in save_data
    mc.add(sql, ls)
  File "E:\time_series_analize\baseClass\baseMysql.py", line 17, in add
    effect_rows = self.cursor.executemany(sql, T)
  File "E:\virtual_environment\time_series\lib\site-packages\pymysql\cursors.py", line 199, in executemany
    self.rowcount = sum(self.execute(query, arg) for arg in args)
  File "E:\virtual_environment\time_series\lib\site-packages\pymysql\cursors.py", line 199, in <genexpr>
    self.rowcount = sum(self.execute(query, arg) for arg in args)
  File "E:\virtual_environment\time_series\lib\site-packages\pymysql\cursors.py", line 170, in execute
    result = self._query(query)
  File "E:\virtual_environment\time_series\lib\site-packages\pymysql\cursors.py", line 328, in _query
    conn.query(q)
  File "E:\virtual_environment\time_series\lib\site-packages\pymysql\connections.py", line 517, in query
    self._affected_rows = self._read_query_result(unbuffered=unbuffered)
  File "E:\virtual_environment\time_series\lib\site-packages\pymysql\connections.py", line 732, in _read_query_result
    result.read()
  File "E:\virtual_environment\time_series\lib\site-packages\pymysql\connections.py", line 1075, in read
    first_packet = self.connection._read_packet()
  File "E:\virtual_environment\time_series\lib\site-packages\pymysql\connections.py", line 684, in _read_packet
    packet.check_error()
  File "E:\virtual_environment\time_series\lib\site-packages\pymysql\protocol.py", line 220, in check_error
    err.raise_mysql_exception(self._data)
  File "E:\virtual_environment\time_series\lib\site-packages\pymysql\err.py", line 109, in raise_mysql_exception
    raise errorclass(errno, errval)
pymysql.err.InternalError: (1411, "Incorrect datetime value: '2019.12.12 16:23:01' for function str_to_date")
2019-12-12 16:24:00 base.py[line:123] INFO Running job "main (trigger: cron[month='1-12', day='12', hour='16', minute='0-59', second='0'], next run at: 2019-12-12 16:25:00 CST)" (scheduled at 2019-12-12 16:24:00+08:00)
2019-12-12 16:24:01 base.py[line:131] ERROR Job "main (trigger: cron[month='1-12', day='12', hour='16', minute='0-59', second='0'], next run at: 2019-12-12 16:25:00 CST)" raised an exception
Traceback (most recent call last):
  File "E:\virtual_environment\time_series\lib\site-packages\apscheduler\executors\base.py", line 125, in run_job
    retval = job.func(*job.args, **job.kwargs)
  File "E:/time_series_analize/main.py", line 47, in main
    save_data(pred_results)
  File "E:\time_series_analize\utils\util.py", line 49, in save_data
    mc.add(sql, ls)
  File "E:\time_series_analize\baseClass\baseMysql.py", line 17, in add
    effect_rows = self.cursor.executemany(sql, T)
  File "E:\virtual_environment\time_series\lib\site-packages\pymysql\cursors.py", line 199, in executemany
    self.rowcount = sum(self.execute(query, arg) for arg in args)
  File "E:\virtual_environment\time_series\lib\site-packages\pymysql\cursors.py", line 199, in <genexpr>
    self.rowcount = sum(self.execute(query, arg) for arg in args)
  File "E:\virtual_environment\time_series\lib\site-packages\pymysql\cursors.py", line 170, in execute
    result = self._query(query)
  File "E:\virtual_environment\time_series\lib\site-packages\pymysql\cursors.py", line 328, in _query
    conn.query(q)
  File "E:\virtual_environment\time_series\lib\site-packages\pymysql\connections.py", line 517, in query
    self._affected_rows = self._read_query_result(unbuffered=unbuffered)
  File "E:\virtual_environment\time_series\lib\site-packages\pymysql\connections.py", line 732, in _read_query_result
    result.read()
  File "E:\virtual_environment\time_series\lib\site-packages\pymysql\connections.py", line 1075, in read
    first_packet = self.connection._read_packet()
  File "E:\virtual_environment\time_series\lib\site-packages\pymysql\connections.py", line 684, in _read_packet
    packet.check_error()
  File "E:\virtual_environment\time_series\lib\site-packages\pymysql\protocol.py", line 220, in check_error
    err.raise_mysql_exception(self._data)
  File "E:\virtual_environment\time_series\lib\site-packages\pymysql\err.py", line 109, in raise_mysql_exception
    raise errorclass(errno, errval)
pymysql.err.InternalError: (1411, "Incorrect datetime value: '2019.12.12 16:24:01' for function str_to_date")
2019-12-12 16:24:49 base.py[line:440] INFO Adding job tentatively -- it will be properly scheduled when the scheduler starts
2019-12-12 16:24:49 base.py[line:881] INFO Added job "main" to job store "default"
2019-12-12 16:24:49 base.py[line:166] INFO Scheduler started
2019-12-12 16:25:00 base.py[line:123] INFO Running job "main (trigger: cron[month='1-12', day='12', hour='16', minute='0-59', second='0'], next run at: 2019-12-12 16:25:00 CST)" (scheduled at 2019-12-12 16:25:00+08:00)
2019-12-12 16:25:01 base.py[line:131] ERROR Job "main (trigger: cron[month='1-12', day='12', hour='16', minute='0-59', second='0'], next run at: 2019-12-12 16:26:00 CST)" raised an exception
Traceback (most recent call last):
  File "E:\virtual_environment\time_series\lib\site-packages\apscheduler\executors\base.py", line 125, in run_job
    retval = job.func(*job.args, **job.kwargs)
  File "E:/time_series_analize/main.py", line 47, in main
    save_data(pred_results)
  File "E:\time_series_analize\utils\util.py", line 49, in save_data
    mc.add(sql, ls)
  File "E:\time_series_analize\baseClass\baseMysql.py", line 17, in add
    effect_rows = self.cursor.executemany(sql, T)
  File "E:\virtual_environment\time_series\lib\site-packages\pymysql\cursors.py", line 199, in executemany
    self.rowcount = sum(self.execute(query, arg) for arg in args)
  File "E:\virtual_environment\time_series\lib\site-packages\pymysql\cursors.py", line 199, in <genexpr>
    self.rowcount = sum(self.execute(query, arg) for arg in args)
  File "E:\virtual_environment\time_series\lib\site-packages\pymysql\cursors.py", line 170, in execute
    result = self._query(query)
  File "E:\virtual_environment\time_series\lib\site-packages\pymysql\cursors.py", line 328, in _query
    conn.query(q)
  File "E:\virtual_environment\time_series\lib\site-packages\pymysql\connections.py", line 517, in query
    self._affected_rows = self._read_query_result(unbuffered=unbuffered)
  File "E:\virtual_environment\time_series\lib\site-packages\pymysql\connections.py", line 732, in _read_query_result
    result.read()
  File "E:\virtual_environment\time_series\lib\site-packages\pymysql\connections.py", line 1075, in read
    first_packet = self.connection._read_packet()
  File "E:\virtual_environment\time_series\lib\site-packages\pymysql\connections.py", line 684, in _read_packet
    packet.check_error()
  File "E:\virtual_environment\time_series\lib\site-packages\pymysql\protocol.py", line 220, in check_error
    err.raise_mysql_exception(self._data)
  File "E:\virtual_environment\time_series\lib\site-packages\pymysql\err.py", line 109, in raise_mysql_exception
    raise errorclass(errno, errval)
pymysql.err.InternalError: (1411, "Incorrect datetime value: '2019.12.12 16:25:01' for function str_to_date")
2019-12-12 16:25:12 base.py[line:440] INFO Adding job tentatively -- it will be properly scheduled when the scheduler starts
2019-12-12 16:25:12 base.py[line:881] INFO Added job "main" to job store "default"
2019-12-12 16:25:12 base.py[line:166] INFO Scheduler started
2019-12-12 16:26:00 base.py[line:123] INFO Running job "main (trigger: cron[month='1-12', day='12', hour='16', minute='0-59', second='0'], next run at: 2019-12-12 16:26:00 CST)" (scheduled at 2019-12-12 16:26:00+08:00)
2019-12-12 16:26:01 base.py[line:131] ERROR Job "main (trigger: cron[month='1-12', day='12', hour='16', minute='0-59', second='0'], next run at: 2019-12-12 16:27:00 CST)" raised an exception
Traceback (most recent call last):
  File "E:\virtual_environment\time_series\lib\site-packages\apscheduler\executors\base.py", line 125, in run_job
    retval = job.func(*job.args, **job.kwargs)
  File "E:/time_series_analize/main.py", line 47, in main
    save_data(pred_results)
  File "E:\time_series_analize\utils\util.py", line 49, in save_data
    mc.add(sql, ls)
  File "E:\time_series_analize\baseClass\baseMysql.py", line 17, in add
    effect_rows = self.cursor.executemany(sql, T)
  File "E:\virtual_environment\time_series\lib\site-packages\pymysql\cursors.py", line 199, in executemany
    self.rowcount = sum(self.execute(query, arg) for arg in args)
  File "E:\virtual_environment\time_series\lib\site-packages\pymysql\cursors.py", line 199, in <genexpr>
    self.rowcount = sum(self.execute(query, arg) for arg in args)
  File "E:\virtual_environment\time_series\lib\site-packages\pymysql\cursors.py", line 170, in execute
    result = self._query(query)
  File "E:\virtual_environment\time_series\lib\site-packages\pymysql\cursors.py", line 328, in _query
    conn.query(q)
  File "E:\virtual_environment\time_series\lib\site-packages\pymysql\connections.py", line 517, in query
    self._affected_rows = self._read_query_result(unbuffered=unbuffered)
  File "E:\virtual_environment\time_series\lib\site-packages\pymysql\connections.py", line 732, in _read_query_result
    result.read()
  File "E:\virtual_environment\time_series\lib\site-packages\pymysql\connections.py", line 1075, in read
    first_packet = self.connection._read_packet()
  File "E:\virtual_environment\time_series\lib\site-packages\pymysql\connections.py", line 684, in _read_packet
    packet.check_error()
  File "E:\virtual_environment\time_series\lib\site-packages\pymysql\protocol.py", line 220, in check_error
    err.raise_mysql_exception(self._data)
  File "E:\virtual_environment\time_series\lib\site-packages\pymysql\err.py", line 109, in raise_mysql_exception
    raise errorclass(errno, errval)
pymysql.err.InternalError: (1411, "Incorrect datetime value: '2019.12.12 16:26:01' for function str_to_date")
2019-12-12 16:26:10 base.py[line:440] INFO Adding job tentatively -- it will be properly scheduled when the scheduler starts
2019-12-12 16:26:10 base.py[line:881] INFO Added job "main" to job store "default"
2019-12-12 16:26:10 base.py[line:166] INFO Scheduler started
2019-12-12 16:27:00 base.py[line:123] INFO Running job "main (trigger: cron[month='1-12', day='12', hour='16', minute='0-59', second='0'], next run at: 2019-12-12 16:27:00 CST)" (scheduled at 2019-12-12 16:27:00+08:00)
2019-12-12 16:27:01 base.py[line:144] INFO Job "main (trigger: cron[month='1-12', day='12', hour='16', minute='0-59', second='0'], next run at: 2019-12-12 16:28:00 CST)" executed successfully
2019-12-12 16:28:00 base.py[line:123] INFO Running job "main (trigger: cron[month='1-12', day='12', hour='16', minute='0-59', second='0'], next run at: 2019-12-12 16:29:00 CST)" (scheduled at 2019-12-12 16:28:00+08:00)
2019-12-12 16:28:01 base.py[line:144] INFO Job "main (trigger: cron[month='1-12', day='12', hour='16', minute='0-59', second='0'], next run at: 2019-12-12 16:29:00 CST)" executed successfully
2019-12-12 16:29:00 base.py[line:123] INFO Running job "main (trigger: cron[month='1-12', day='12', hour='16', minute='0-59', second='0'], next run at: 2019-12-12 16:30:00 CST)" (scheduled at 2019-12-12 16:29:00+08:00)
2019-12-12 16:29:01 base.py[line:144] INFO Job "main (trigger: cron[month='1-12', day='12', hour='16', minute='0-59', second='0'], next run at: 2019-12-12 16:30:00 CST)" executed successfully
2019-12-12 16:33:38 base.py[line:440] INFO Adding job tentatively -- it will be properly scheduled when the scheduler starts
2019-12-12 16:33:38 base.py[line:881] INFO Added job "main" to job store "default"
2019-12-12 16:33:38 base.py[line:166] INFO Scheduler started
2019-12-12 16:34:00 base.py[line:123] INFO Running job "main (trigger: cron[month='1-12', day='12', hour='16', minute='0-59', second='0'], next run at: 2019-12-12 16:34:00 CST)" (scheduled at 2019-12-12 16:34:00+08:00)
2019-12-12 16:34:01 base.py[line:131] ERROR Job "main (trigger: cron[month='1-12', day='12', hour='16', minute='0-59', second='0'], next run at: 2019-12-12 16:35:00 CST)" raised an exception
Traceback (most recent call last):
  File "E:\virtual_environment\time_series\lib\site-packages\apscheduler\executors\base.py", line 125, in run_job
    retval = job.func(*job.args, **job.kwargs)
  File "E:/time_series_analize/main.py", line 47, in main
    save_data(pred_results)
  File "E:\time_series_analize\utils\util.py", line 50, in save_data
    mc.add(sql, ls)
  File "E:\time_series_analize\baseClass\baseMysql.py", line 17, in add
    effect_rows = self.cursor.executemany(sql, T)
  File "E:\virtual_environment\time_series\lib\site-packages\pymysql\cursors.py", line 199, in executemany
    self.rowcount = sum(self.execute(query, arg) for arg in args)
  File "E:\virtual_environment\time_series\lib\site-packages\pymysql\cursors.py", line 199, in <genexpr>
    self.rowcount = sum(self.execute(query, arg) for arg in args)
  File "E:\virtual_environment\time_series\lib\site-packages\pymysql\cursors.py", line 170, in execute
    result = self._query(query)
  File "E:\virtual_environment\time_series\lib\site-packages\pymysql\cursors.py", line 328, in _query
    conn.query(q)
  File "E:\virtual_environment\time_series\lib\site-packages\pymysql\connections.py", line 517, in query
    self._affected_rows = self._read_query_result(unbuffered=unbuffered)
  File "E:\virtual_environment\time_series\lib\site-packages\pymysql\connections.py", line 732, in _read_query_result
    result.read()
  File "E:\virtual_environment\time_series\lib\site-packages\pymysql\connections.py", line 1075, in read
    first_packet = self.connection._read_packet()
  File "E:\virtual_environment\time_series\lib\site-packages\pymysql\connections.py", line 684, in _read_packet
    packet.check_error()
  File "E:\virtual_environment\time_series\lib\site-packages\pymysql\protocol.py", line 220, in check_error
    err.raise_mysql_exception(self._data)
  File "E:\virtual_environment\time_series\lib\site-packages\pymysql\err.py", line 109, in raise_mysql_exception
    raise errorclass(errno, errval)
pymysql.err.ProgrammingError: (1064, "You have an error in your SQL syntax; check the manual that corresponds to your MySQL server version for the right syntax to use near 'int(MAX_FORECAST_COUNT)) \n            and MIN_FORECAST_COUNT=values(int(MIN_FORE' at line 5")
2019-12-12 16:35:00 base.py[line:123] INFO Running job "main (trigger: cron[month='1-12', day='12', hour='16', minute='0-59', second='0'], next run at: 2019-12-12 16:36:00 CST)" (scheduled at 2019-12-12 16:35:00+08:00)
2019-12-12 16:35:01 base.py[line:131] ERROR Job "main (trigger: cron[month='1-12', day='12', hour='16', minute='0-59', second='0'], next run at: 2019-12-12 16:36:00 CST)" raised an exception
Traceback (most recent call last):
  File "E:\virtual_environment\time_series\lib\site-packages\apscheduler\executors\base.py", line 125, in run_job
    retval = job.func(*job.args, **job.kwargs)
  File "E:/time_series_analize/main.py", line 47, in main
    save_data(pred_results)
  File "E:\time_series_analize\utils\util.py", line 50, in save_data
    mc.add(sql, ls)
  File "E:\time_series_analize\baseClass\baseMysql.py", line 17, in add
    effect_rows = self.cursor.executemany(sql, T)
  File "E:\virtual_environment\time_series\lib\site-packages\pymysql\cursors.py", line 199, in executemany
    self.rowcount = sum(self.execute(query, arg) for arg in args)
  File "E:\virtual_environment\time_series\lib\site-packages\pymysql\cursors.py", line 199, in <genexpr>
    self.rowcount = sum(self.execute(query, arg) for arg in args)
  File "E:\virtual_environment\time_series\lib\site-packages\pymysql\cursors.py", line 170, in execute
    result = self._query(query)
  File "E:\virtual_environment\time_series\lib\site-packages\pymysql\cursors.py", line 328, in _query
    conn.query(q)
  File "E:\virtual_environment\time_series\lib\site-packages\pymysql\connections.py", line 517, in query
    self._affected_rows = self._read_query_result(unbuffered=unbuffered)
  File "E:\virtual_environment\time_series\lib\site-packages\pymysql\connections.py", line 732, in _read_query_result
    result.read()
  File "E:\virtual_environment\time_series\lib\site-packages\pymysql\connections.py", line 1075, in read
    first_packet = self.connection._read_packet()
  File "E:\virtual_environment\time_series\lib\site-packages\pymysql\connections.py", line 684, in _read_packet
    packet.check_error()
  File "E:\virtual_environment\time_series\lib\site-packages\pymysql\protocol.py", line 220, in check_error
    err.raise_mysql_exception(self._data)
  File "E:\virtual_environment\time_series\lib\site-packages\pymysql\err.py", line 109, in raise_mysql_exception
    raise errorclass(errno, errval)
pymysql.err.ProgrammingError: (1064, "You have an error in your SQL syntax; check the manual that corresponds to your MySQL server version for the right syntax to use near 'int(MAX_FORECAST_COUNT)) \n            and MIN_FORECAST_COUNT=values(int(MIN_FORE' at line 5")
2019-12-12 16:35:30 base.py[line:440] INFO Adding job tentatively -- it will be properly scheduled when the scheduler starts
2019-12-12 16:35:30 base.py[line:881] INFO Added job "main" to job store "default"
2019-12-12 16:35:30 base.py[line:166] INFO Scheduler started
2019-12-12 16:36:00 base.py[line:123] INFO Running job "main (trigger: cron[month='1-12', day='12', hour='16', minute='0-59', second='0'], next run at: 2019-12-12 16:36:00 CST)" (scheduled at 2019-12-12 16:36:00+08:00)
2019-12-12 16:36:01 base.py[line:144] INFO Job "main (trigger: cron[month='1-12', day='12', hour='16', minute='0-59', second='0'], next run at: 2019-12-12 16:37:00 CST)" executed successfully
2019-12-12 16:37:00 base.py[line:123] INFO Running job "main (trigger: cron[month='1-12', day='12', hour='16', minute='0-59', second='0'], next run at: 2019-12-12 16:38:00 CST)" (scheduled at 2019-12-12 16:37:00+08:00)
2019-12-12 16:37:01 base.py[line:144] INFO Job "main (trigger: cron[month='1-12', day='12', hour='16', minute='0-59', second='0'], next run at: 2019-12-12 16:38:00 CST)" executed successfully
2019-12-12 16:38:00 base.py[line:123] INFO Running job "main (trigger: cron[month='1-12', day='12', hour='16', minute='0-59', second='0'], next run at: 2019-12-12 16:39:00 CST)" (scheduled at 2019-12-12 16:38:00+08:00)
2019-12-12 16:38:01 base.py[line:144] INFO Job "main (trigger: cron[month='1-12', day='12', hour='16', minute='0-59', second='0'], next run at: 2019-12-12 16:39:00 CST)" executed successfully
2019-12-12 16:39:00 base.py[line:123] INFO Running job "main (trigger: cron[month='1-12', day='12', hour='16', minute='0-59', second='0'], next run at: 2019-12-12 16:40:00 CST)" (scheduled at 2019-12-12 16:39:00+08:00)
2019-12-12 16:39:01 base.py[line:144] INFO Job "main (trigger: cron[month='1-12', day='12', hour='16', minute='0-59', second='0'], next run at: 2019-12-12 16:40:00 CST)" executed successfully
2019-12-12 16:40:00 base.py[line:123] INFO Running job "main (trigger: cron[month='1-12', day='12', hour='16', minute='0-59', second='0'], next run at: 2019-12-12 16:41:00 CST)" (scheduled at 2019-12-12 16:40:00+08:00)
2019-12-12 16:40:01 base.py[line:144] INFO Job "main (trigger: cron[month='1-12', day='12', hour='16', minute='0-59', second='0'], next run at: 2019-12-12 16:41:00 CST)" executed successfully
2019-12-12 16:41:00 base.py[line:123] INFO Running job "main (trigger: cron[month='1-12', day='12', hour='16', minute='0-59', second='0'], next run at: 2019-12-12 16:42:00 CST)" (scheduled at 2019-12-12 16:41:00+08:00)
2019-12-12 16:41:01 base.py[line:144] INFO Job "main (trigger: cron[month='1-12', day='12', hour='16', minute='0-59', second='0'], next run at: 2019-12-12 16:42:00 CST)" executed successfully
2019-12-12 16:41:55 base.py[line:440] INFO Adding job tentatively -- it will be properly scheduled when the scheduler starts
2019-12-12 16:41:55 base.py[line:881] INFO Added job "main" to job store "default"
2019-12-12 16:41:55 base.py[line:166] INFO Scheduler started
2019-12-12 16:42:00 base.py[line:123] INFO Running job "main (trigger: cron[month='1-12', day='12', hour='16', minute='0-59', second='0'], next run at: 2019-12-12 16:42:00 CST)" (scheduled at 2019-12-12 16:42:00+08:00)
2019-12-12 16:42:01 base.py[line:144] INFO Job "main (trigger: cron[month='1-12', day='12', hour='16', minute='0-59', second='0'], next run at: 2019-12-12 16:43:00 CST)" executed successfully
2019-12-12 16:43:00 base.py[line:123] INFO Running job "main (trigger: cron[month='1-12', day='12', hour='16', minute='0-59', second='0'], next run at: 2019-12-12 16:44:00 CST)" (scheduled at 2019-12-12 16:43:00+08:00)
2019-12-12 16:43:01 base.py[line:144] INFO Job "main (trigger: cron[month='1-12', day='12', hour='16', minute='0-59', second='0'], next run at: 2019-12-12 16:44:00 CST)" executed successfully
2019-12-12 16:44:00 base.py[line:123] INFO Running job "main (trigger: cron[month='1-12', day='12', hour='16', minute='0-59', second='0'], next run at: 2019-12-12 16:45:00 CST)" (scheduled at 2019-12-12 16:44:00+08:00)
2019-12-12 16:44:01 base.py[line:144] INFO Job "main (trigger: cron[month='1-12', day='12', hour='16', minute='0-59', second='0'], next run at: 2019-12-12 16:45:00 CST)" executed successfully
2019-12-12 16:45:00 base.py[line:123] INFO Running job "main (trigger: cron[month='1-12', day='12', hour='16', minute='0-59', second='0'], next run at: 2019-12-12 16:46:00 CST)" (scheduled at 2019-12-12 16:45:00+08:00)
2019-12-12 16:45:01 base.py[line:144] INFO Job "main (trigger: cron[month='1-12', day='12', hour='16', minute='0-59', second='0'], next run at: 2019-12-12 16:46:00 CST)" executed successfully
2019-12-12 17:29:05 base.py[line:440] INFO Adding job tentatively -- it will be properly scheduled when the scheduler starts
2019-12-12 17:29:05 base.py[line:881] INFO Added job "main" to job store "default"
2019-12-12 17:29:05 base.py[line:166] INFO Scheduler started
2019-12-12 17:30:09 base.py[line:440] INFO Adding job tentatively -- it will be properly scheduled when the scheduler starts
2019-12-12 17:30:09 base.py[line:881] INFO Added job "main" to job store "default"
2019-12-12 17:30:09 base.py[line:166] INFO Scheduler started
2019-12-12 17:31:58 base.py[line:440] INFO Adding job tentatively -- it will be properly scheduled when the scheduler starts
2019-12-12 17:31:58 base.py[line:881] INFO Added job "main" to job store "default"
2019-12-12 17:31:58 base.py[line:166] INFO Scheduler started
2019-12-12 17:33:23 base.py[line:440] INFO Adding job tentatively -- it will be properly scheduled when the scheduler starts
2019-12-12 17:33:23 base.py[line:881] INFO Added job "main" to job store "default"
2019-12-12 17:33:23 base.py[line:166] INFO Scheduler started
2019-12-12 17:34:00 base.py[line:123] INFO Running job "main (trigger: cron[month='1-12', day='12', hour='17', minute='0-59', second='0'], next run at: 2019-12-12 17:34:00 CST)" (scheduled at 2019-12-12 17:34:00+08:00)
2019-12-12 17:34:01 base.py[line:131] ERROR Job "main (trigger: cron[month='1-12', day='12', hour='17', minute='0-59', second='0'], next run at: 2019-12-12 17:35:00 CST)" raised an exception
Traceback (most recent call last):
  File "E:\virtual_environment\time_series\lib\site-packages\apscheduler\executors\base.py", line 125, in run_job
    retval = job.func(*job.args, **job.kwargs)
  File "E:/time_series_analize/main.py", line 47, in main
    save_data(pred_results)
  File "E:\time_series_analize\utils\util.py", line 50, in save_data
    mc_formal(sql, ls)
TypeError: 'MysqlConn' object is not callable
2019-12-12 17:34:35 base.py[line:440] INFO Adding job tentatively -- it will be properly scheduled when the scheduler starts
2019-12-12 17:34:35 base.py[line:881] INFO Added job "main" to job store "default"
2019-12-12 17:34:35 base.py[line:166] INFO Scheduler started
2019-12-12 17:35:00 base.py[line:123] INFO Running job "main (trigger: cron[month='1-12', day='12', hour='17', minute='0-59', second='0'], next run at: 2019-12-12 17:35:00 CST)" (scheduled at 2019-12-12 17:35:00+08:00)
2019-12-12 17:35:01 base.py[line:144] INFO Job "main (trigger: cron[month='1-12', day='12', hour='17', minute='0-59', second='0'], next run at: 2019-12-12 17:36:00 CST)" executed successfully
2019-12-12 17:36:00 base.py[line:123] INFO Running job "main (trigger: cron[month='1-12', day='12', hour='17', minute='0-59', second='0'], next run at: 2019-12-12 17:37:00 CST)" (scheduled at 2019-12-12 17:36:00+08:00)
2019-12-12 17:36:01 base.py[line:144] INFO Job "main (trigger: cron[month='1-12', day='12', hour='17', minute='0-59', second='0'], next run at: 2019-12-12 17:37:00 CST)" executed successfully
2019-12-16 10:51:46 base.py[line:440] INFO Adding job tentatively -- it will be properly scheduled when the scheduler starts
2019-12-16 10:51:46 base.py[line:881] INFO Added job "main" to job store "default"
2019-12-16 10:51:46 base.py[line:166] INFO Scheduler started
2019-12-16 10:52:00 base.py[line:123] INFO Running job "main (trigger: cron[month='1-12', day='16', hour='10', minute='0-59', second='0'], next run at: 2019-12-16 10:52:00 CST)" (scheduled at 2019-12-16 10:52:00+08:00)
2019-12-16 10:52:01 base.py[line:144] INFO Job "main (trigger: cron[month='1-12', day='16', hour='10', minute='0-59', second='0'], next run at: 2019-12-16 10:53:00 CST)" executed successfully
2019-12-16 10:57:44 base.py[line:440] INFO Adding job tentatively -- it will be properly scheduled when the scheduler starts
2019-12-16 10:57:44 base.py[line:881] INFO Added job "main" to job store "default"
2019-12-16 10:57:44 base.py[line:166] INFO Scheduler started
2019-12-16 10:58:00 base.py[line:123] INFO Running job "main (trigger: cron[month='1-12', day='16', hour='10', minute='0-59', second='0'], next run at: 2019-12-16 10:58:00 CST)" (scheduled at 2019-12-16 10:58:00+08:00)
2019-12-16 10:58:01 base.py[line:144] INFO Job "main (trigger: cron[month='1-12', day='16', hour='10', minute='0-59', second='0'], next run at: 2019-12-16 10:59:00 CST)" executed successfully
